Workbook

Sheet Front Sheet
I15: CONTRACT SUM ANALYSIS
I17: RELATING TO
I19: 10060 - EASTWOOD ESTATE NORTH
I21: AT
I23: EASTWOOD ESTATE
I24: LONDON N15

Sheet Cost Summary
A1: Cost Summary | C1: Cost Summary
C3: Ref | D3: Main Summary | E3: Total
C5: A | D5: PRELIMINARIES (Brought Forward) | E5: ='A1-Preliminaries'!H234 -> 1236865
C7: B | D7: DESIGN AND DEVELOPMENT COSTS (Brought Forward) | E7: ='B-Design and Development Costs'!D83 -> 0
C9: C | D9: DEMOLITIONS AND SITE CLEARANCE (Brought Forward) | E9: ='C-Demolition & Site Clearance'!D53 -> 90960.894
C11: D | D11: CONSTRUCTION COSTS
C13: D1 | D13: Building: Block N1: Passivhaus Classic (Brought Forward) | E13: ='D1 Building Block N1'!F272 -> 2304792.3
C15: D2 | D15: Building: Block N7: Passivhaus Low Energy (Brought Forward) | E15: ='D2 Building Block N7'!F244 -> 792157.31
C17: D3 | D17: Building: Community Clubroom Refurbishment (Brought Forward) | E17: ='D3 Clubroom Refurb'!F24 -> 31165
C19: D4 | D19: External Works to New Development (Brought Forward) | E19: ='D4 External Works'!D175 -> 712951.18
C22: E | D22: CONTRACTOR'S PROPOSALS (Brought Forward) | E22: ='E-Contractor''s Proposals'!D66 -> 0
C24: F | D24: WORKS OUTSIDE THE BOUNDARY OF THE SITE (Brought Forward) | E24: ='F-Works outside the boundary'!D46 -> 206521.51
C26: G | D26: AFTERCARE (Brought Forward) | E26: ='G-Aftercare'!D62 -> 0
D28: Sub-Total: Building Works | E28: =SUM(E4:E27) -> 5375413.2
C30: H | D30: OVERHEADS AND PROFIT
D32: The Contractor shall here insert the percentage adjustment required on expenditure against project variations and provisional sums where not measurable in line with the Contract Sum Analysis.
D33: Overhead: ………… % (please insert percentage) | E33: incl
D34: Profit: ………… % (please insert percentage) | E34: incl
C36: I | D36: PERFORMANCE BOND
D37: 10% to be allowed as per ER's | E37: 14474.682
C38: J | D38: CONTRACTOR’S INSURANCES | E38: 0
C40: K | D40: INSURANCE UNDER CONTRACT CLAUSE 6.5.1 | E40: 0
D42: Total Building Works | E42: =SUM(E28:E41) -> 5389887.9
D44: Below the line item:
C46: L | D46: ALTERNATIVE COSTS (Brought Forward) | E46: ='G-Aftercare'!D84 -> 0

Sheet Tender Instructions
A1: Instructions for tenders:
A3: 1 | B3: Bidders must fully price the item of these price schedule and ensure that their total tender price has been transferred correctly to the Cost Summary page and Form of Tender.
A5: 2 | B5: All cells must be completed.
A7: 3 | B7: All tender bids will be are evaluated and scored accordantly. Tenders with a deviation of 20% or more from the MEAN value will be required to provide further documentation to support there financial proposals.
A9: 4 | B9: Following confirmation of appointment, the winner tender could be required to provide further breakdown to there proposals.

Sheet Tender Qualifications
A1: Tender Qualifications:
B3: Please list any Tender Qualifications below:
A5: 1 | B5: Preliminaries
B6: Programme is based on a XXX month duration
B7: Assumes site compound for each site - N1 and N7
B8: Assumes 1no Welfare - complete with site Office, Canteen, Drying Room, Toilet Block, with other as a "satellite" - Portaloo and Office
B9: Assumes wet waste will be connected to existing sewage
B10: Allows for 1no Tower Crane to build N1, complete with hardstanding and all necessary ancillaries
B11: Alllows for 1no Telehandler to build N7
B12: No allowance for Oversail licence currently
B13: Scaffolding Monflex allowed only to N7 due to proximity of neighbours
B14: CCTV to be provided by monitored system, 2no locations - covering N1 and N7 compound
B15: Saftey Hoarding to be provided as timber, complete with sign boards (provided by others). Allowing for 1no Pedestrian Gate, 1no Vehicle Gate. No allowance for Biometric turnstile and the like
B16: Tree Protection to be erected and maintained for the duration of the contract, ownership remianing the responsibility of the contractor
B17: Tree Root Protection to Grounds will be installed and maintained for the duration of the contract, ownership remaining the responsibility of the contractor
A20: 2 | B20: Design and Development Costs
B21: Provisional Sums allowed only - due to information being requested for the Novation of contracts from design team
B22: Quotations for the Mains Services not received, as indicated from ITT ER's Clause 9.2.2
A25: 3 | B25: Demolition & Site Clearance
B26: Allows for demolition of existing Garages
B27: Allows for demolition of existing screen walls
B28: Allows for demolition of existing Muga
B29: Allows for area to be segregated whilst works are in progress
B30: Allows for works as seen and identiffied within the reports
A32: 4 | B32: Construction Works - Building Block N1, Building Block N7
B33: N1 - Piling Works allows for 46no piles, 450mm dia @ max depth of 18m. Subject to change on final piling designs
B34: N7 - Standard Trench Foundations
B35: N1 - to be constructed as a Reinforced Concrete Frame
B36: N7 - to be constructed as masonry construction with Hollowcore plank flooring
B37: Windows and Doors to be Aluminium - as specified Nordan Manufacturer
B38: Internal Specification as per Internal Schedule - 3849-LB-ZZ-ZZ-L-A-550020_Internal Finishes Schedule-C01
B39: No appliances allowed for in either block
A41: 5 | B41: Clubroom Refurb
B42: Provisional Sums allowed for at present - no details present
A44: 6 | B44: External Works
B45: Allows for all roads and paths as indetified within the civils and structural pack
B46: Allows for removal of Trees as identified on drawings
B47: Allows for New Soft Landscaping
B48: Allows for New Hardlandscaping
B49: Allows for New Street Furniture
...

Sheet A- Preliminaries Summary
A1: A1- Preliminaries Summary
A3: Ref | B3: Element | D3: Total
A5: A | B5: Site Accommodation | C5: £ | D5: ='A1-Preliminaries'!H42 -> 93578
A7: B | B7: Site Records | C7: £ | D7: ='A1-Preliminaries'!H46 -> 0
A9: C | B9: Completion and Post Completion Requirements | C9: £ | D9: ='A1-Preliminaries'!H62 -> 0
A11: D | B11: Management & Staff | C11: £ | D11: ='A1-Preliminaries'!H91 -> 431080
A13: E | B13: Temporary Services | C13: £ | D13: ='A1-Preliminaries'!H112 -> 111600
A15: F | B15: Scaffolding | C15: £ | D15: ='A1-Preliminaries'!H123 -> 222670
A17: G | B17: Security | C17: £ | D17: ='A1-Preliminaries'!H130 -> 16640
A19: H | B19: Safety & Environment Protection | C19: £ | D19: ='A1-Preliminaries'!H143 -> 73550
A21: I | B21: Control & Protection | C21: £ | D21: ='A1-Preliminaries'!H153 -> 9100
A23: J | B23: Mechanical Plant | C23: £ | D23: ='A1-Preliminaries'!H167 -> 137149
A25: K | B25: Temporary Works | C25: £ | D25: ='A1-Preliminaries'!H175 -> 0
A27: L | B27: Completion & Post Completion Requirement | C27: £ | D27: ='A1-Preliminaries'!H187 -> 69128
A29: M | B29: Cleaning | C29: £ | D29: ='A1-Preliminaries'!H198 -> 0
A31: N | B31: Fees and charges | C31: £ | D31: ='A1-Preliminaries'!H213 -> 10000
A33: O | B33: Insurance bonds | C33: £ | D33: ='A1-Preliminaries'!H231 -> 62370
A35: P | B35: Marketing | C35: £ | D35: ='A1-Preliminaries'!#REF! -> #REF!
B38: Preliminaries Total | C38: £ | D38: =SUM(D4:D37) -> #REF!

Sheet A1-Preliminaries
A1: A1- Cost Breakdown - Preliminaries
H2: Project Duration | I2: 52
A3: Contractors Proposed Programme Duration inclusive of lead in
A6: Ref | B6: Element | C6: Rate/week | D6: Number | E6: %age | F6: Weeks | H6: Total | I6: Comments
A8: A | B8: Site Accommodation
A9: 1 | B9: Office Accommodation | C9: =35+15 -> 50 | D9: 1 | E9: 1 | F9: =$I$2 -> 52 | G9: £ | H9: =C9*D9*E9*F9 -> 2600
A10: 2 | B10: Site Setup & establishment costs | C10: 10000 | D10: 1 | E10: 1 | F10: 1 | G10: £ | H10: =C10*D10*E10*F10 -> 10000 | I10: Fixed cost (not weekly) | J10: Assumes hardstanding
A11: 3 | B11: Site removal costs | C11: 2000 | D11: 1 | E11: 1 | F11: 1 | G11: £ | H11: =C11*D11*E11*F11 -> 2000 | I11: Fixed cost (not weekly)
A12: 4 | B12: Site reinstatement costs | G12: £ | H12: =C12*D12*E12*F12 -> 0 | I12: Fixed cost (not weekly)
A13: 5 | B13: Canteen units | C13: 35 | D13: 1 | E13: 1 | F13: =$I$2 -> 52 | G13: £ | H13: =C13*D13*E13*F13 -> 1820
A14: 6 | B14: Drying rooms | C14: 35 | D14: 2 | E14: 1 | F14: =$I$2 -> 52 | G14: £ | H14: =C14*D14*E14*F14 -> 3640
A15: 7 | B15: Toilet units | C15: 25 | D15: 2 | E15: 1 | F15: =$I$2 -> 52 | G15: £ | H15: =C15*D15*E15*F15 -> 2600
A16: 8 | B16: Transport & erect temp accommodation | C16: =850+110+14 -> 974 | D16: 4 | E16: 1 | F16: 1 | G16: £ | H16: =C16*D16*E16*F16 -> 3896
A17: 9 | B17: Furniture | C17: 16 | D17: 1 | E17: 1 | F17: =$I$2 -> 52 | G17: £ | H17: =C17*D17*E17*F17 -> 832
A18: 10 | B18: Fire extinguishers, fitting out & the like | F18: =$I$2 -> 52 | G18: £ | H18: =C18*D18*E18*F18 -> 0
A19: 11 | B19: Rates on temporary buildings | F19: =$I$2 -> 52 | G19: £ | H19: =C19*D19*E19*F19 -> 0
A20: 12 | B20: General Welfare consumables | C20: 215 | D20: 2 | E20: 1 | F20: =$I$2 -> 52 | G20: £ | H20: =C20*D20*E20*F20 -> 22360
A21: 13 | B21: Demobilisation costs | C21: 5000 | D21: 1 | E21: 1 | F21: 1 | G21: £ | H21: =C21*D21*E21*F21 -> 5000
A22: 14 | B22: Temp electrics - installation & equipment | F22: 1 | G22: £ | H22: =C22*D22*E22*F22 -> 0 | I22: Fixed cost (not weekly)
A23: 15 | B23: Temp water - ditto | F23: =$I$2 -> 52 | G23: £ | H23: =C23*D23*E23*F23 -> 0
A24: 16 | B24: Drainage temp connections | F24: 1 | G24: £ | H24: =C24*D24*E24*F24 -> 0 | I24: Fixed cost (not weekly)
A25: 17 | B25: Telephone installation | C25: 750 | D25: 1 | E25: 1 | F25: 1 | G25: £ | H25: =C25*D25*E25*F25 -> 750
A26: 18 | B26: Telephone rental & system charges | C26: 15 | D26: 1 | E26: 1 | F26: =$I$2 -> 52 | G26: £ | H26: =C26*D26*E26*F26 -> 780
A27: 19 | B27: IT Installations | C27: 100 | D27: 1 | E27: 1 | F27: =$I$2 -> 52 | G27: £ | H27: =C27*D27*E27*F27 -> 5200
A28: 20 | B28: Waste Management | C28: =350 -> 350 | D28: 1 | E28: 1 | F28: =$I$2 -> 52 | G28: £ | H28: =C28*D28*E28*F28 -> 18200
A29: 21 | B29: Condition surveys, records & photos | C29: 2500 | D29: 1 | E29: 1 | F29: 1 | G29: £ | H29: =C29*D29*E29*F29 -> 2500 | J29: Plugged
A30: 22 | B30: Progress Photography | C30: 25 | D30: 1 | E30: 1 | F30: =$I$2 -> 52 | G30: £ | H30: =C30*D30*E30*F30 -> 1300
A31: 23 | B31: Mobile phones | C31: 25 | D31: 2 | E31: 1 | F31: =$I$2 -> 52 | G31: £ | H31: =C31*D31*E31*F31 -> 2600
A32: 24 | B32: O&M manuals + As Built Drawings + completion packs | F32: 1 | G32: £ | H32: =C32*D32*E32*F32 -> 0 | J32: Check if these are done in house
A33: 25 | B33: Considerate Constructor Scheme | C33: 850 | D33: 1 | E33: 1 | F33: 1 | G33: £ | H33: =C33*D33*E33*F33 -> 850 | I33: Fixed cost (not weekly) | J33: Check considerate contractors
A34: 26 | B34: Petty cash | F34: 1 | G34: £ | H34: =C34*D34*E34*F34 -> 0 | I34: Fixed cost (not weekly)
A35: 27 | B35: SAP Rating calculation & certification | C35: 1650 | D35: 1 | E35: 1 | F35: 1 | G35: £ | H35: =C35*D35*E35*F35 -> 1650 | J35: Get rate from BSRIA
A36: 28 | B36: Passivhaus Liaison and documentation | C36: 5000 | D36: 1 | E36: 1 | F36: 1 | G36: £ | H36: =C36*D36*E36*F36 -> 5000 | I36: Fixed cost (not weekly) | J36: Plugged
A37: 29 | B37: (Contractor to state any additional items below) | G37: £ | H37: =C37*D37*E37*F37 -> 0
A38: 30 | G38: £ | H38: =C38*D38*E38*F38 -> 0
A39: 31 | G39: £ | H39: =C39*D39*E39*F39 -> 0
A40: 32 | G40: £ | H40: =C40*D40*E40*F40 -> 0
A41: 33 | G41: £ | H41: =C41*D41*E41*F41 -> 0
A42: A | B42: Section total: | G42: £ | H42: =SUM(H9:H41) -> 93578
A44: B | B44: Site Records
...

Sheet B-Design and Development Costs
A1: B - Cost Breakdown - Design and Development Costs
A3: Ref | B3: Element | D3: Total | H3: Cost | I3: 0.05 | J3: Rate to be used
B5: Design Team Fees
A6: 1 | B6: Architect
B7: Stage 4 - Technical Design | C7: £ | D7: =J7 -> 0 | I7: =H7*$I$3 -> 0 | J7: =SUM(H7:I7) -> 0 | K7: plugged - provisional
B8: Stage 5+ - Manufacturing and Construction | C8: £ | D8: =J8 -> 0 | I8: =H8*$I$3 -> 0 | J8: =SUM(H8:I8) -> 0
A10: 2 | B10: Structural Engineer | C10: £ | D10: =J10 -> 0 | I10: =H10*$I$3 -> 0 | J10: =SUM(H10:I10) -> 0
A13: 3 | B13: Mechanical and Electrical
B14: Stage 4 - Technical Design | C14: £ | D14: =J14 -> 0 | I14: =H14*$I$3 -> 0 | J14: =SUM(H14:I14) -> 0
B15: Stage 5 - Manufacturing and Construction | C15: £ | D15: =J15 -> 0 | I15: =H15*$I$3 -> 0 | J15: =SUM(H15:I15) -> 0
B16: Stage 6 - Handover | C16: £ | D16: =J16 -> 0 | I16: =H16*$I$3 -> 0 | J16: =SUM(H16:I16) -> 0
B17: Stage 7 - Use | C17: £ | D17: =J17 -> 0 | I17: =H17*$I$3 -> 0 | J17: =SUM(H17:I17) -> 0
A19: 4 | B19: Landscape Architect
B20: Stage 4 - Technical Design | C20: £ | D20: =J20 -> 0 | I20: =H20*$I$3 -> 0 | J20: =SUM(H20:I20) -> 0
B21: Stage 5 - Manufacturing and Construction | C21: £ | D21: =J21 -> 0 | I21: =H21*$I$3 -> 0 | J21: =SUM(H21:I21) -> 0
A23: 5 | B23: Other Designers - please specify
B24: Fire Engineer | C24: £ | D24: =J24 -> 0 | I24: =H24*$I$3 -> 0 | J24: =SUM(H24:I24) -> 0
B25: SAP assessor / incl. SAP, PEA & EPC certificates | C25: £ | D25: =J25 -> 0 | I25: =H25*$I$3 -> 0 | J25: =SUM(H25:I25) -> 0
C26: £ | D26: =J26 -> 0 | I26: =H26*$I$3 -> 0 | J26: =SUM(H26:I26) -> 0
B29: Local &Statutory Authority Costs
A30: 6 | B30: Planning Conditions | C30: £ | D30: =J30 -> 0 | I30: =H30*$I$3 -> 0 | J30: =SUM(H30:I30) -> 0
A31: 7 | B31: Building Control | C31: £ | D31: =J31 -> 0 | I31: =H31*$I$3 -> 0 | J31: =SUM(H31:I31) -> 0
A32: 8 | B32: Adoptable Works | C32: £ | D32: =J32 -> 0 | I32: =H32*$I$3 -> 0 | J32: =SUM(H32:I32) -> 0
A33: 9 | B33: Water Authority | C33: £ | D33: =J33 -> 0 | I33: =H33*$I$3 -> 0 | J33: =SUM(H33:I33) -> 0
A34: 10 | B34: UKPN | C34: £ | D34: =J34 -> 0 | I34: =H34*$I$3 -> 0 | J34: =SUM(H34:I34) -> 0
A35: 11 | B35: Gas | C35: £ | D35: =J35 -> 0 | I35: =H35*$I$3 -> 0 | J35: =SUM(H35:I35) -> 0
A36: 12 | B36: Highways inc. bonds | C36: £ | D36: =J36 -> 0 | I36: =H36*$I$3 -> 0 | J36: =SUM(H36:I36) -> 0
A37: 13 | B37: Section 106 | C37: £ | D37: =J37 -> 0 | I37: =H37*$I$3 -> 0 | J37: =SUM(H37:I37) -> 0
A38: 14 | B38: Section 104 | C38: £ | D38: =J38 -> 0 | I38: =H38*$I$3 -> 0 | J38: =SUM(H38:I38) -> 0
A39: 15 | B39: All other Local Authority cost:
B43: Site Surveys
A44: 16 | B44: Ground Investigations | C44: £ | D44: =J44 -> 0 | I44: =H44*$I$3 -> 0 | J44: =SUM(H44:I44) -> 0
A45: 17 | B45: Topographical | C45: £ | D45: =J45 -> 0 | I45: =H45*$I$3 -> 0 | J45: =SUM(H45:I45) -> 0
A46: 18 | B46: Asbestos | C46: £ | D46: =J46 -> 0 | I46: =H46*$I$3 -> 0 | J46: =SUM(H46:I46) -> 0
A47: 19 | B47: Ecological | C47: £ | D47: =J47 -> 0 | I47: =H47*$I$3 -> 0 | J47: =SUM(H47:I47) -> 0
A48: 20 | B48: Vibration & Noise Monitoring | C48: £ | D48: =J48 -> 0 | I48: =H48*$I$3 -> 0 | J48: =SUM(H48:I48) -> 0
B50: Certification
A51: 21 | B51: Energy Performance Certificates | C51: £ | D51: =J51 -> 0 | I51: =H51*$I$3 -> 0 | J51: =SUM(H51:I51) -> 0
A52: 22 | B52: Sound Tests | C52: £ | D52: =J52 -> 0 | I52: =H52*$I$3 -> 0 | J52: =SUM(H52:I52) -> 0
A53: 23 | B53: Air Tightness | C53: £ | D53: =J53 -> 0 | I53: =H53*$I$3 -> 0 | J53: =SUM(H53:I53) -> 0
...

Sheet C-Demolition & Site Clearance
A1: C - Cost Breakdown - Demolitions and Site Clearance
A3: Ref | B3: Element | D3: Total | H3: Cost | I3: 0.15 | J3: Rate to be used
A5: 1 | B5: Demolition of structures on site | C5: £ | D5: =J5 -> 82335.894 | H5: 71596.43 | I5: =H5*I3 -> 10739.464 | J5: =SUM(H5:I5) -> 82335.894
A7: 2 | B7: Site Clearance | C7: £ | D7: incl
A9: 3 | B9: Remediation of contaminated earth | C9: £ | D9: excl
A11: 4 | B11: Excavation and levelling | C11: £ | D11: incl
A13: 5 | B13: All other demolitions and site clearance required for the works | C13: £ | D13: incl
A15: 6 | B15: Temporary works for demolition and site clearance | C15: £ | D15: incl
A17: 7 | B17: All other demolition works - Please specify below: | C17: £
A19: 8 | B19: Protection of existing block | C19: £ | D19: =J19 -> 8625 | H19: 7500 | I19: =H19*I3 -> 1125 | J19: =SUM(H19:I19) -> 8625 | K19: Provisional Sum
B53: Carried To Summary | C53: £ | D53: =SUM(D4:D52) -> 90960.894

Sheet D1 Building Block N1
A1: D1 - BUILDING: BLOCK N1 | M1: 5200
A3: Ref | B3: Element | D3: Elemental Total | F3: To Cost Summary | H3: Cost | I3: 0.15 | J3: Rate to be used
A5: 1 | B5: Substructure
A7: 1.1 | B7: Excavation works | C7: £ | D7: =J7 -> 6211.863 | H7: 5401.62 | I7: =H7*$I$3 -> 810.243 | J7: =SUM(H7:I7) -> 6211.863 | M7: =D7/$M$1 -> 1.194589
D8: =J8 -> 0 | M8: =D8/$M$1 -> 0
A9: 1.2 | B9: Standard foundations | D9: =J9 -> 0 | I9: =H9*$I$3 -> 0 | J9: =SUM(H9:I9) -> 0 | M9: =D9/$M$1 -> 0
D10: =J10 -> 0 | M10: =D10/$M$1 -> 0
A11: 1.3 | B11: Specialist foundations (piling mat, pile caps, pilling, etc.) | C11: £ | D11: =J11 -> 159775.16 | H11: =51519.92+87415 -> 138934.92 | I11: =H11*$I$3 -> 20840.238 | J11: =SUM(H11:I11) -> 159775.16 | M11: =D11/$M$1 -> 30.725992
D12: =J12 -> 0 | M12: =D12/$M$1 -> 0
A13: 1.3 | B13: Ground beams & ground floor slab | C13: £ | D13: =J13 -> 82671.637 | H13: 71888.38 | I13: =H13*$I$3 -> 10783.257 | J13: =SUM(H13:I13) -> 82671.637 | M13: =D13/$M$1 -> 15.898392
D14: =J14 -> 0 | M14: =D14/$M$1 -> 0
A15: 1.4 | B15: Retaining walls | C15: £ | D15: =J15 -> 0 | I15: =H15*$I$3 -> 0 | J15: =SUM(H15:I15) -> 0 | M15: =D15/$M$1 -> 0
D16: =J16 -> 0 | M16: =D16/$M$1 -> 0
A17: 1.5 | B17: Insulation | C17: £ | D17: =J17 -> 17733 | H17: 15420 | I17: =H17*$I$3 -> 2313 | J17: =SUM(H17:I17) -> 17733 | M17: =D17/$M$1 -> 3.4101923
D18: =J18 -> 0 | M18: =D18/$M$1 -> 0
A19: 1.6 | B19: All other substructure items and matters (please specify below): | D19: =J19 -> 0 | I19: =H19*$I$3 -> 0 | J19: =SUM(H19:I19) -> 0 | M19: =D19/$M$1 -> 0
B20: Lift pits | C20: £ | D20: =J20 -> 0 | I20: =H20*$I$3 -> 0 | J20: =SUM(H20:I20) -> 0 | M20: =D20/$M$1 -> 0
B21: Sundry works | C21: £ | D21: =J21 -> 270.25 | H21: 235 | I21: =H21*$I$3 -> 35.25 | J21: =SUM(H21:I21) -> 270.25 | M21: =D21/$M$1 -> 0.051971154
B22: Scaffold bases | C22: £ | D22: =J22 -> 0 | I22: =H22*$I$3 -> 0 | J22: =SUM(H22:I22) -> 0 | K22: Included within piling mat | M22: =D22/$M$1 -> 0
C23: £ | D23: =J23 -> 0 | I23: =H23*$I$3 -> 0 | J23: =SUM(H23:I23) -> 0 | M23: =D23/$M$1 -> 0
C24: £ | D24: =J24 -> 0 | I24: =H24*$I$3 -> 0 | J24: =SUM(H24:I24) -> 0 | M24: =D24/$M$1 -> 0
I25: =H25*$I$3 -> 0 | J25: =SUM(H25:I25) -> 0 | M25: =D25/$M$1 -> 0
D26: Substructure Sub-Total | E26: £ | F26: =SUM(D5:D24) -> 266661.91 | I26: =H26*$I$3 -> 0 | J26: =SUM(H26:I26) -> 0 | M26: =D26/$M$1 -> #VALUE!
I27: =H27*$I$3 -> 0 | J27: =SUM(H27:I27) -> 0 | M27: =D27/$M$1 -> 0
A28: 2 | B28: Superstructure | I28: =H28*$I$3 -> 0 | J28: =SUM(H28:I28) -> 0 | M28: =D28/$M$1 -> 0
I29: =H29*$I$3 -> 0 | J29: =SUM(H29:I29) -> 0 | M29: =D29/$M$1 -> 0
A30: 2.1 | B30: Frame | I30: =H30*$I$3 -> 0 | J30: =SUM(H30:I30) -> 0 | M30: =D30/$M$1 -> 0
M31: =D31/$M$1 -> 0
B32: Concrete frames - Ground Floor | C32: £ | D32: =J32 -> 0 | I32: =H32*$I$3 -> 0 | J32: =SUM(H32:I32) -> 0 | M32: =D32/$M$1 -> 0
A33: 2.1.2 | B33: Reinforced In-situ Concrete | C33: £ | D33: =J33 -> 4947.116 | H33: =2354.24+1498.15+449.45 -> 4301.84 | I33: =H33*$I$3 -> 645.276 | J33: =SUM(H33:I33) -> 4947.116 | M33: =D33/$M$1 -> 0.95136846
A34: 2.1.3 | B34: Formwork for Reinforced In-situ Concrete | C34: £ | D34: =J34 -> 12812.794 | H34: 11141.56 | I34: =H34*$I$3 -> 1671.234 | J34: =SUM(H34:I34) -> 12812.794 | M34: =D34/$M$1 -> 2.4639988
A35: 2.1.4 | B35: Reinforcement | C35: £ | D35: =J35 -> 5954.4125 | H35: 5177.75 | I35: =H35*$I$3 -> 776.6625 | J35: =SUM(H35:I35) -> 5954.4125 | M35: =D35/$M$1 -> 1.1450793
A36: 2.1.5 | B36: Concrete surface finishes | C36: £ | D36: =J36 -> 301.7025 | H36: 262.35 | I36: =H36*$I$3 -> 39.3525 | J36: =SUM(H36:I36) -> 301.7025 | M36: =D36/$M$1 -> 0.058019712
A37: 2.1.6 | B37: Forming holes (Diameter NE 150mm) | C37: £ | D37: =J37 -> 1207.5 | H37: =175*6 -> 1050 | I37: =H37*$I$3 -> 157.5 | J37: =SUM(H37:I37) -> 1207.5 | M37: =D37/$M$1 -> 0.23221154
B38: Concrete frames - First Floor | D38: =J38 -> 0 | M38: =D38/$M$1 -> 0
A39: 2.1.7 | B39: Reinforced In-situ Concrete | C39: £ | D39: =J39 -> 13607.766 | H39: 11832.84 | I39: =H39*$I$3 -> 1774.926 | J39: =SUM(H39:I39) -> 13607.766 | M39: =D39/$M$1 -> 2.6168781
A40: 2.1.8 | B40: Formwork for Reinforced In-situ Concrete | C40: £ | D40: =J40 -> 22969.824 | H40: 19973.76 | I40: =H40*$I$3 -> 2996.064 | J40: =SUM(H40:I40) -> 22969.824 | M40: =D40/$M$1 -> 4.4172738
A41: 2.1.9 | B41: Reinforcement | C41: £ | D41: =J41 -> 14826.087 | H41: 12892.25 | I41: =H41*$I$3 -> 1933.8375 | J41: =SUM(H41:I41) -> 14826.087 | M41: =D41/$M$1 -> 2.8511707
A42: 2.1.10 | B42: Concrete surface finishes | C42: £ | D42: =J42 -> 1449.0575 | H42: 1260.05 | I42: =H42*$I$3 -> 189.0075 | J42: =SUM(H42:I42) -> 1449.0575 | M42: =D42/$M$1 -> 0.2786649
A43: 2.1.11 | B43: Forming holes (Diameter NE 150mm) | C43: £ | D43: =J43 -> 1207.5 | H43: =175*6 -> 1050 | I43: =H43*$I$3 -> 157.5 | J43: =SUM(H43:I43) -> 1207.5 | M43: =D43/$M$1 -> 0.23221154
...

Sheet D2 Building Block N7
A1: D2 - BUILDING: BLOCK N7
A3: Ref | B3: Element | D3: Elemental Total | F3: To Cost Summary | H3: Cost | I3: 0.15 | J3: Rate to be used
A5: 1 | B5: Substructure
A7: 1.1 | B7: Excavation works | C7: £ | D7: =J7 -> 16865.268 | H7: 14665.45 | I7: =H7*$I$3 -> 2199.8175 | J7: =SUM(H7:I7) -> 16865.268
D8: =J8 -> 0
A9: 1.2 | B9: Standard foundations | D9: =J9 -> 11969.43 | H9: =8290.8+1367+277.2+473.2 -> 10408.2 | I9: =H9*$I$3 -> 1561.23 | J9: =SUM(H9:I9) -> 11969.43
D10: =J10 -> 0
A11: 1.3 | B11: Specialist foundations (piling mat, pile caps, pilling, etc.) | C11: £ | D11: =J11 -> 0 | I11: =H11*$I$3 -> 0 | J11: =SUM(H11:I11) -> 0
D12: =J12 -> 0
A13: 1.3 | B13: Ground beams | C13: £ | D13: =J13 -> 0 | I13: =H13*$I$3 -> 0 | J13: =SUM(H13:I13) -> 0
D14: =J14 -> 0
A15: 1.4 | B15: Retaining walls | C15: £ | D15: =J15 -> 0 | I15: =H15*$I$3 -> 0 | J15: =SUM(H15:I15) -> 0
D16: =J16 -> 0
A17: 1.5 | B17: Ground floor slab | C17: £ | D17: =J17 -> 14520.59 | H17: 12626.6 | I17: =H17*$I$3 -> 1893.99 | J17: =SUM(H17:I17) -> 14520.59
D18: =J18 -> 0
A19: 1.6 | B19: Insulation | C19: £ | D19: =J19 -> 0 | I19: =H19*$I$3 -> 0 | J19: =SUM(H19:I19) -> 0
D20: =J20 -> 0 | I20: =H20*$I$3 -> 0 | J20: =SUM(H20:I20) -> 0
A21: 1.7 | B21: All other substructure items and matters (please specify below): | C21: £ | D21: =J21 -> 0 | I21: =H21*$I$3 -> 0 | J21: =SUM(H21:I21) -> 0
B22: Brickwork up to DPC | C22: £ | D22: =J22 -> 15588.342 | H22: 13555.08 | I22: =H22*$I$3 -> 2033.262 | J22: =SUM(H22:I22) -> 15588.342
B23: Blockwork up to DPC | C23: £ | D23: =J23 -> 7470.354 | H23: 6495.96 | I23: =H23*$I$3 -> 974.394 | J23: =SUM(H23:I23) -> 7470.354
B24: Scaffold bases | C24: £ | D24: =J24 -> 1779.096 | H24: 1547.04 | I24: =H24*$I$3 -> 232.056 | J24: =SUM(H24:I24) -> 1779.096
C25: £ | D25: =J25 -> 0 | I25: =H25*$I$3 -> 0 | J25: =SUM(H25:I25) -> 0
C26: £ | D26: =J26 -> 0 | I26: =H26*$I$3 -> 0 | J26: =SUM(H26:I26) -> 0
I27: =H27*$I$3 -> 0 | J27: =SUM(H27:I27) -> 0
D28: Substructure Sub-Total | E28: £ | F28: =SUM(D5:D26) -> 68193.08 | I28: =H28*$I$3 -> 0 | J28: =SUM(H28:I28) -> 0
I29: =H29*$I$3 -> 0 | J29: =SUM(H29:I29) -> 0
A30: 2 | B30: Superstructure | I30: =H30*$I$3 -> 0 | J30: =SUM(H30:I30) -> 0
I31: =H31*$I$3 -> 0 | J31: =SUM(H31:I31) -> 0
A32: 2.1 | B32: Frame | I32: =H32*$I$3 -> 0 | J32: =SUM(H32:I32) -> 0
I33: =H33*$I$3 -> 0 | J33: =SUM(H33:I33) -> 0
A34: 2.1.1 | B34: Steel frame | I34: =H34*$I$3 -> 0 | J34: =SUM(H34:I34) -> 0
A35: 2.1.1.1 | B35: Structural steel frame | C35: £ | D35: =J35 -> 42527.506 | H35: =18845.54+18134.9 -> 36980.44 | I35: =H35*$I$3 -> 5547.066 | J35: =SUM(H35:I35) -> 42527.506
A36: 2.1.1.2 | B36: Fire protection to steel frame | C36: £ | D36: =J36 -> 6465.99 | H36: 5622.6 | I36: =H36*$I$3 -> 843.39 | J36: =SUM(H36:I36) -> 6465.99
D37: =J37 -> 0 | I37: =H37*$I$3 -> 0 | J37: =SUM(H37:I37) -> 0
D38: =J38 -> 0 | I38: =H38*$I$3 -> 0 | J38: =SUM(H38:I38) -> 0
A39: 2.2 | B39: Upper Floors | D39: =J39 -> 0 | I39: =H39*$I$3 -> 0 | J39: =SUM(H39:I39) -> 0
D40: =J40 -> 0 | I40: =H40*$I$3 -> 0 | J40: =SUM(H40:I40) -> 0
A41: 2.2.1 | B41: Concrete Floors | C41: £ | D41: =J41 -> 0 | I41: =H41*$I$3 -> 0 | J41: =SUM(H41:I41) -> 0
B42: Hollocore precast floor | C42: £ | D42: =J42 -> 20731.05 | H42: 18027 | I42: =H42*$I$3 -> 2704.05 | J42: =SUM(H42:I42) -> 20731.05
B43: Insulation | C43: £ | D43: =J43 -> 0 | I43: =H43*$I$3 -> 0 | J43: =SUM(H43:I43) -> 0
...

Sheet D3 Clubroom Refurb
A1: D2 - BUILDING: BLOCK N7
A3: Ref | B3: Element | D3: Elemental Total | F3: To Cost Summary | H3: Cost | I3: 0.15 | J3: Rate to be used
A5: 7 | B5: Refurbishment Works
B6: Community Clubroom
A8: 1.1 | B8: Remove razor wire. | C8: £ | D8: =J8 -> 1725 | H8: 1500 | I8: =H8*$I$3 -> 225 | J8: =SUM(H8:I8) -> 1725
A10: 1.2 | B10: All front, rear and some upper windows all need to be replaced (high security and controlled/restricted opening), with high quality toughened/laminated and high efficient double glazed units. | C10: £ | D10: =J10 -> 20700 | H10: =900*20 -> 18000 | I10: =H10*$I$3 -> 2700 | J10: =SUM(H10:I10) -> 20700
A12: 1.3 | B12: Fanlight windows to be bricked up. | C12: £ | D12: =J12 -> 2587.5 | H12: =450*5 -> 2250 | I12: =H12*$I$3 -> 337.5 | J12: =SUM(H12:I12) -> 2587.5 | M12: £450 per opening x 5
A14: 1.4 | B14: Remove and replace the existing plain main entrance security door and surround should be replaced with high security door entrance door. | C14: £ | D14: =J14 -> 2012.5 | H14: 1750 | I14: =H14*$I$3 -> 262.5 | J14: =SUM(H14:I14) -> 2012.5 | M14: £1500 for security door
A16: 1.5 | B16: Replacment of street lighting. | C16: £ | D16: =J16 -> 4140 | H16: 3600 | I16: =H16*$I$3 -> 540 | J16: =SUM(H16:I16) -> 4140
D21: Substructure Sub-Total | E21: £ | F21: =SUM(D5:D19) -> 31165
D24: Carried To Summary | E24: £ | F24: =F21 -> 31165

Sheet D4 External Works
A1: D3 - External Works to New Development
A3: A | B3: Pricing notes on external works
B4: - Tenders are required to price all individual items listed below
A7: Ref | B7: Element | D7: Total | H7: Cost | I7: 0.15 | J7: Rate to be used
A9: 8.1 | B9: Site Preparation Works
A10: 8.1.1 | B10: Site clearance | C10: £ | D10: =J10 -> 0 | E10: included elsewhere | I10: =H10*$I$7 -> 0 | J10: =SUM(H10:I10) -> 0
A11: 8.1.2 | B11: Excavation and levelling | C11: £ | D11: =J11 -> 0 | I11: =H11*$I$7 -> 0 | J11: =SUM(H11:I11) -> 0
A12: 8.1.3 | B12: Tree removal | C12: £ | D12: =J12 -> 0 | I12: =H12*$I$7 -> 0 | J12: =SUM(H12:I12) -> 0
A13: 8.1.4 | B13: Trees protection | C13: £ | D13: =J13 -> 0 | I13: =H13*$I$7 -> 0 | J13: =SUM(H13:I13) -> 0
A14: 8.1.5 | B14: Minor demolition works | C14: £ | D14: =J14 -> 0 | I14: =H14*$I$7 -> 0 | J14: =SUM(H14:I14) -> 0
B15: Remove existing infill brick wall | C15: £ | D15: =J15 -> 0 | E15: included elsewhere | I15: =H15*$I$7 -> 0 | J15: =SUM(H15:I15) -> 0
B16: Remove existing play equipment and set aside for reuse. | C16: £ | D16: =J16 -> 0 | E16: included elsewhere | I16: =H16*$I$7 -> 0 | J16: =SUM(H16:I16) -> 0
B17: Remove BT telephone box, existing railings | C17: £ | D17: =J17 -> 0 | E17: included elsewhere | I17: =H17*$I$7 -> 0 | J17: =SUM(H17:I17) -> 0
D18: =J18 -> 0 | I18: =H18*$I$7 -> 0 | J18: =SUM(H18:I18) -> 0
D19: =J19 -> 0 | I19: =H19*$I$7 -> 0 | J19: =SUM(H19:I19) -> 0
A20: 8.2 | B20: Roads, Paths, Pavings and Surfacing | D20: =J20 -> 0 | I20: =H20*$I$7 -> 0 | J20: =SUM(H20:I20) -> 0
A21: 8.2.1 | B21: P01 Tarmac - N7 | C21: £ | D21: =J21 -> 13816.135 | H21: =11969.78+44.25 -> 12014.03 | I21: =H21*$I$7 -> 1802.1045 | J21: =SUM(H21:I21) -> 13816.135 | K21: LECI
A22: 8.2.2 | B22: P02a Impermeable coloured asphalt - N1 | C22: £ | D22: =J22 -> 23564.535 | H22: 20490.9 | I22: =H22*$I$7 -> 3073.635 | J22: =SUM(H22:I22) -> 23564.535 | K22: LECI
A23: 8.2.3 | B23: P02a Impermeable coloured asphalt - N7 | C23: £ | D23: =J23 -> 17638.631 | H23: 15337.94 | I23: =H23*$I$7 -> 2300.691 | J23: =SUM(H23:I23) -> 17638.631 | K23: LECI
A24: 8.2.4 | B24: P02b Permeable coloured asphalt | C24: £ | D24: =J24 -> 7607.8595 | H24: 6615.53 | I24: =H24*$I$7 -> 992.3295 | J24: =SUM(H24:I24) -> 7607.8595 | K24: LECI
A25: 8.2.5 | B25: Resurface new road - remove existing & resurface | C25: £ | D25: =J25 -> 36773.55 | H25: 31977 | I25: =H25*$I$7 -> 4796.55 | J25: =SUM(H25:I25) -> 36773.55
A26: 8.2.6 | B26: P04 Wet pour play safety surface | C26: £ | D26: =J26 -> 60570.477 | H26: =13992.78+38677.2 -> 52669.98 | I26: =H26*$I$7 -> 7900.497 | J26: =SUM(H26:I26) -> 60570.477
A27: 8.2.7 | B27: P03 Playground surface - Break up existing surface | C27: £ | D27: =J27 -> 0 | I27: =H27*$I$7 -> 0 | J27: =SUM(H27:I27) -> 0
A28: 8.2.8 | B28: P03 Upgraded MUGA surface | C28: £ | D28: =J28 -> 52957.5 | E28: Prov Sum | H28: =150*307 -> 46050 | I28: =H28*$I$7 -> 6907.5 | J28: =SUM(H28:I28) -> 52957.5
A29: 8.2.9 | B29: Painting existing Muga | C29: £ | D29: =J29 -> 0 | I29: =H29*$I$7 -> 0 | J29: =SUM(H29:I29) -> 0
A30: 8.2.10 | B30: P05 PCC flag pavers - N1 | C30: £ | D30: =J30 -> 3176.438 | H30: 2762.12 | I30: =H30*$I$7 -> 414.318 | J30: =SUM(H30:I30) -> 3176.438 | K30: LECI
A31: 8.2.11 | B31: P05 PCC flag pavers - N7 | C31: £ | D31: =J31 -> 4557.496 | H31: 3963.04 | I31: =H31*$I$7 -> 594.456 | J31: =SUM(H31:I31) -> 4557.496 | K31: LECI
A32: 8.2.12 | B32: Zebra crossing allowance | C32: £ | D32: =J32 -> 1725 | H32: 1500 | I32: =H32*$I$7 -> 225 | J32: =SUM(H32:I32) -> 1725 | K32: plugged rate
A33: 8.2.13 | B33: New footpath | C33: £ | D33: =J33 -> 3677.7 | H33: 3198 | I33: =H33*$I$7 -> 479.7 | J33: =SUM(H33:I33) -> 3677.7
A34: 8.2.14 | B34: Car Parking | C34: £ | D34: =J34 -> 23872.792 | H34: 20758.95 | I34: =H34*$I$7 -> 3113.8425 | J34: =SUM(H34:I34) -> 23872.792
A35: 8.2.15 | B35: PCC Kerb - N1 | C35: £ | D35: =J35 -> 2408.951 | H35: 2094.74 | I35: =H35*$I$7 -> 314.211 | J35: =SUM(H35:I35) -> 2408.951 | K35: LECI
A36: 8.2.16 | B36: PCC Edging - N1 | C36: £ | D36: =J36 -> 2949.75 | H36: =2565 -> 2565 | I36: =H36*$I$7 -> 384.75 | J36: =SUM(H36:I36) -> 2949.75 | K36: LECI
A37: 8.2.17 | B37: PCC Kerb - N7 | C37: £ | D37: =J37 -> 5047.35 | H37: 4389 | I37: =H37*$I$7 -> 658.35 | J37: =SUM(H37:I37) -> 5047.35 | K37: LECI
A38: 8.2.18 | B38: PCC Edging - N7 | C38: £ | D38: =J38 -> 2979.2475 | H38: 2590.65 | I38: =H38*$I$7 -> 388.5975 | J38: =SUM(H38:I38) -> 2979.2475 | K38: LECI
D39: =J39 -> 0 | I39: =H39*$I$7 -> 0 | J39: =SUM(H39:I39) -> 0
D40: =J40 -> 0 | I40: =H40*$I$7 -> 0 | J40: =SUM(H40:I40) -> 0
A41: 8.3 | B41: Soft Landscaping, Planting and Irrigation Systems | D41: =J41 -> 0 | I41: =H41*$I$7 -> 0 | J41: =SUM(H41:I41) -> 0
A42: 8.3.1 | B42: PL01 Defensible buffer planting | C42: £ | D42: =J42 -> 12309.014 | H42: =338.91+1007.49+274.13+379.99+960.63+864.07+2140.65+939.33+864.07+957.08+948.56+301.78+377.62+349.18 -> 10703.49 | I42: =H42*$I$7 -> 1605.5235 | J42: =SUM(H42:I42) -> 12309.014
A43: 8.3.2 | B43: PL02 - Suds Planting | C43: £ | D43: =J43 -> 16210.032 | H43: =638.4+1324.8+819.2+904+771.2+747.2+2080.8+2659.68+1958.4+780.8+632+779.2 -> 14095.68 | I43: =H43*$I$7 -> 2114.352 | J43: =SUM(H43:I43) -> 16210.032
A44: 8.3.3 | B44: PL03 Boundary Planting | C44: £ | D44: =J44 -> 15953.743 | H44: =444.05+541.08+435.49+314.28+318.86+459.03+463.32+333.72+459.03+426.6+459.03+542.49+459.03+677.31+476.15+7063.35 -> 13872.82 | I44: =H44*$I$7 -> 2080.923 | J44: =SUM(H44:I44) -> 15953.743
...

Sheet E-Contractor's Proposals
A1: E - Cost Breakdown - Contractor's Proposals
A3: Ref | B3: Element | D3: Total
A5: F | B5: CONTRACTOR'S PROPOSALS
B7: The Contractor is to list below:-
A9: 1 | B9: Any other costs attributable to any items of work not specifically identified within the Contract Sum Analysis but included by the Contractor in his tender
A13: 2 | B13: Any items included by the Contractor which are in addition to or deviate from the Employer's Requirements
B17: Please provide breakdown itemised items below (to be insert by the contractor):
C20: £ | D20: =SUM(C20:C20) -> 0
C22: £ | D22: =SUM(C22:C22) -> 0
C24: £ | D24: =SUM(C24:C24) -> 0
C26: £ | D26: =SUM(C26:C26) -> 0
C28: £ | D28: =SUM(C28:C28) -> 0
C30: £ | D30: =SUM(C30:C30) -> 0
C32: £ | D32: =SUM(C32:C32) -> 0
C34: £ | D34: =SUM(C34:C34) -> 0
C36: £ | D36: =SUM(C36:C36) -> 0
B66: Carried To Summary | C66: £ | D66: =SUM(D4:D65) -> 0

Sheet F-Works outside the boundary
A1: F - Cost Breakdown - Works outside the boundary of the site
A3: Ref | B3: Element | D3: Total | H3: Cost | I3: 0.15 | J3: Rate to be used
A5: F | B5: WORKS OUTSIDE THE BOUNDARY OF THE SITE
B7: Please refer to the following tender documents for guidelines on pricing:
B9: The Contractor is to list below:-
B11: New cycle bases around the development | C11: £ | D11: =J11 -> 33109.88 | H11: 28791.2 | I11: =H11*$I$3 -> 4318.68 | J11: =SUM(H11:I11) -> 33109.88
I12: =H12*$I$3 -> 0 | J12: =SUM(H12:I12) -> 0
B13: New cycle storage units | C13: £ | D13: =J13 -> 166750 | H13: 145000 | I13: =H13*$I$3 -> 21750 | J13: =SUM(H13:I13) -> 166750
I14: =H14*$I$3 -> 0 | J14: =SUM(H14:I14) -> 0
B15: Wall to be rebuilt | C15: £ | D15: =J15 -> 2300 | H15: 2000 | I15: =H15*$I$3 -> 300 | J15: =SUM(H15:I15) -> 2300
I16: =H16*$I$3 -> 0 | J16: =SUM(H16:I16) -> 0
B17: White lining | C17: £ | D17: =J17 -> 1552.5 | H17: 1350 | I17: =H17*$I$3 -> 202.5 | J17: =SUM(H17:I17) -> 1552.5
I18: =H18*$I$3 -> 0 | J18: =SUM(H18:I18) -> 0
B19: Hardlandscaping to be lifted and replaced with soft landscaping | C19: £ | D19: =J19 -> 2809.128 | H19: 2442.72 | I19: =H19*$I$3 -> 366.408 | J19: =SUM(H19:I19) -> 2809.128
B46: Carried To Summary | C46: £ | D46: =SUM(D4:D45) -> 206521.51

Sheet G-Aftercare
A1: G - Cost Breakdown - Aftercare
A3: Ref | B3: Element | D3: Total
A5: H | B5: AFTERCARE - 24 MONTHS DEFECTS
A7: 1 | B7: General | C7: £ | D7: =SUM(C7:C7) -> 0
A9: 2 | B9: Soft Landscaping | C9: £
A11: 3 | B11: Green & Brown roofs | C11: £ | D11: =SUM(C11:C11) -> 0
A13: 4 | B13: Roof access & mansafe systems | C13: £ | D13: =SUM(C13:C13) -> 0
A15: 5 | B15: Lifts | C15: £ | D15: =SUM(C15:C15) -> 0
A17: 6 | B17: M+E | C17: £ | D17: =SUM(C17:C17) -> 0
A19: 7 | B19: Plant Equipment | C19: £ | D19: =SUM(C19:C19) -> 0
A21: 8 | B21: Water storage & Booster Tanks | C21: £ | D21: =SUM(C21:C21) -> 0
A23: 9 | B23: IRS System | C23: £ | D23: =SUM(C23:C23) -> 0
A25: 10 | B25: PVs | C25: £ | D25: =SUM(C25:C25) -> 0
A27: 11 | B27: ASHPs | C27: £ | D27: =SUM(C27:C27) -> 0
A29: 12 | B29: AOVs | C29: £ | D29: =SUM(C29:C29) -> 0
A31: 13 | B31: Fire Alarm System | C31: £ | D31: =SUM(C31:C31) -> 0
A33: 14 | B33: Door Entry System | C33: £ | D33: =SUM(C33:C33) -> 0
... A37: 16 | B37: Out of Hours Emergency Defects Team | C37: £ | D37: =SUM(C37:C37) -> 0
A39: 17 | B39: Please list below any other items that the contractor deems necessary:
C41: £ | D41: =SUM(C41:C41) -> 0
C43: £ | D43: =SUM(C43:C43) -> 0
C45: £ | D45: =SUM(C45:C45) -> 0
C47: £ | D47: =SUM(C47:C47) -> 0
C49: £ | D49: =SUM(C49:C49) -> 0
C51: £ | D51: =SUM(C51:C51) -> 0
C53: £ | D53: =SUM(C53:C53) -> 0
C55: £ | D55: =SUM(C55:C55) -> 0
C57: £ | D57: =SUM(C57:C57) -> 0
C59: £ | D59: =SUM(C59:C59) -> 0
B62: Carried To Summary | C62: £ | D62: =SUM(D5:D60) -> 0

Sheet L-Alternative Costs
A1: M - Alternative Costs
A3: Ref | B3: Element | D3: Total
J4: 10.76
B5: Please provide your cost proposals for the alternative items below: | I5: =491.97-82.23 -> 409.74 | J5: =I5*J4 -> 4408.8024 | K5: 689787 | L5: =K5/J5 -> 156.45677
I6: 192.06 | J6: =I6*J4 -> 2066.5656 | K6: 194104 | L6: =K6/J6 -> 93.925884
A7: 1 | B7: Parent Company Guarantee (PCG) | C7: £ | D7: =SUM(C7:C7) -> 0 | L7: =L5-L6 -> 62.53089
A9: 2 | C9: £ | D9: =SUM(C9:C9) -> 0
A11: 3 | C11: £ | D11: =SUM(C11:C11) -> 0
A13: 4 | C13: £ | D13: =SUM(C13:C13) -> 0
A15: 5 | C15: £ | D15: =SUM(C15:C15) -> 0
A17: 6 | C17: £ | D17: =SUM(C17:C17) -> 0
A19: 7 | C19: £ | D19: =SUM(C19:C19) -> 0
B49: Carried To Summary | C49: £ | D49: =SUM(D4:D48) -> 0
