Workbook

Sheet Summary
A2: ='02 Plot Groundworks'!A2 -> The Former Police Station, Haslingden | C2: SUMMARY
B6: SUMMARY | C6: Page Nr | D6: Total
D7: £
B9: SECTION 1 - PRELIMINARIES | D9: ='01 Prelims'!E63 -> 352400
B11: SECTION 2 - PLOT GROUNDWORKS | D11: ='02 Plot Groundworks'!F39 -> 14410.65
B13: SECTION 3 - EXTERNAL GROUNDWORKS | D13: =SUM('03 External Groundworks'!F270,'03 External Groundworks'!F200,'03 External Groundworks'!F129,'03 External Groundworks'!F49) -> 159217.9
B15: SECTION 4 - EXTERNAL FAÇADE | D15: =SUM('04 External Facade'!F59,'04 External Facade'!F92) -> 132676.43
B17: SECTION 5 - DRYLINING, SCREED & RENDER | D17: =SUM('05 Drylining, Screed & Render'!F44,'05 Drylining, Screed & Render'!F74,'05 Drylining, Screed & Render'!F115,'05 Drylining, Screed & Render'!F146) -> 140587.78
B19: SECTION 6 - M&E | D19: =SUM('06 M&E'!F38) -> 168400
B21: SECTION 7 - CARPENTRY | D21: =SUM('07 Carpentry'!F45,'07 Carpentry'!F81,'07 Carpentry'!F118,'07 Carpentry'!F161,'07 Carpentry'!F197,'07 Carpentry'!F234) -> 49353.92
B23: SECTION 8 - ROOF COVERINGS | D23: =SUM('08 Roof Coverings'!F38) -> 67381.943
B25: SECTION 9 - DECORATING AND OTHER FINISHINGS | D25: =SUM('09 Decorating & Other Finishing'!F57,'09 Decorating & Other Finishing'!F97) -> 199797.8
B27: SECTION 10 - MATERIALS | D27: =SUM('10 Materials'!F66,'10 Materials'!F130) -> 267184.45
B29: SECTION 11 - LANDSCAPING | D29: =SUM('11 Landscaping'!F64) -> 8344
B31: SECTION 12 - WALLS & FENCES | D31: =SUM('12 Walls & Fences'!F64) -> 41894
B33: Sub total | D33: =SUM(D9:D32) -> 1601648.9
B35: Add overheads and profit | C35: 0.15 | D35: =D33*C35 -> 240247.33
B37: Total Sqft | C37: =SUM('09 Decorating & Other Finishing'!C10,'09 Decorating & Other Finishing'!C14) -> 10142
B39: Build cost per sqft (Plot works only) | C39: =SUM(D11,D15,D17,D19,D21,D23,D25,D27,'01 Prelims'!E45)/C37 -> 109.22826
B41: Entire site cost per sqft | C41: =SUM(D9:D31)/C37 -> 157.92239
B46: CARRIED TO FORM OF TENDER | C46: £ | D46: =SUM(D33:D44) -> 1841896.2

Sheet 00 General Clarifications
B2: General Assumptions & Clarifications (to be read in conjunction with those within each tab of the work schedule)
B4: Ref. | C4: General Assumption/Clarification
C5: These assumptions & clarifications are to be read in conjunction with those within each tab of the work schedule
C6: We note the site is served by power, water and telecoms and assume we will be able to connect to these services and have beneficial use during the works
C7: We have made no allowances for taking control of any statutory authority quotations for utilites on or off site.
C8: Any on site material will need to be WAC tested before dispoal from site, this can be arranged by the contractor for an additional fee.
C9: Full soil investigation information will need to be provided to the contractor before the cost for cart away can be established - all cart away assumed Inert
C10: We have assumed that any potential habitat/ecology issues, such as bats, badgers, tree protection, etc., will not have a detrimental effect on programme
C11: We have made no allowance for any making good of the highway, surfaces, verges, fencing, etc., leading to site, and do not accept any responsibility for any damage caused during the progress of the works
C12: We agree the use of JCT ICD 2016 unamended (except for retention to be at 3%) is appropriate for this project
C13: We have forecast a programme period of 48 weeks on site
C14: We will require the early payment of any supplier deposits/stage payments, etc., as per their terms to ensure the smooth running of the project. We will try to time these payments to suit valuation dates, but in some instances it may require an interim payment. We are happy to investigate Vesting as required
C15: We have assumed that all information supplied for pricing purposes is accurate, and we have the right to additional time and/or costs if the tender information is proven to be insufficient or cannot be relied upon
C16: We have assumed that all directly employed/nominated suppliers can meet the dates required within our programme, and any delay caused or due to any directly employed/nominated suppliers will be subject to additional time and/or cost
... C25: We have assumed vacant possession and uninterrupted access to the site at all times

Sheet 01 Prelims
A2: =Summary!A2 -> The Former Police Station, Haslingden | D2: PRELIMINARIES
A4: Description | B4: Quantity | C4: Unit | D4: Rate | E4: £
A5: Contract period | B5: 48 | C5: wks
A7: Supervision & Labour
A8: Contracts Manager (1.5 day/week) | B8: 44 | C8: wks | D8: 750 | E8: =ROUND(B8 * D8,2) -> 33000
A9: Site Manager | B9: =$B$5 -> 48 | C9: wks | D9: 1750 | E9: =ROUND(B9 * D9,2) -> 84000
A10: Quantity Surveyor (1.5 day/week) | B10: =$B$5 -> 48 | C10: wks | D10: 750 | E10: =ROUND(B10 * D10,2) -> 36000
A11: Temporary Works Design - done by Structural engineer | B11: 1 | C11: PS | D11: 0 | E11: =ROUND(B11 * D11,2) -> 0
A12: Labourer | B12: =$B$5 -> 48 | C12: wks | D12: 500 | E12: =ROUND(B12 * D12,2) -> 24000
A13: Forklift Driver | B13: 40 | C13: wks | D13: 880 | E13: =ROUND(B13 * D13,2) -> 35200
A14: Setting out | B14: 2 | C14: wks | D14: 1500 | E14: =ROUND(B14 * D14,2) -> 3000
A16: Site Offices, Compound & Security
A17: Formation of site office and welfare area in basement including dismantling when works to basement due to commence | B17: 1 | C17: item | D17: 2220 | E17: =ROUND(B17 * D17,2) -> 2220
A18: Formation of site office and welfare area in basement including dismantling when works to basement due to commence | C18: wks | E18: Excluded
A19: Site office/meeting room & steps | B19: 48 | C19: wks | D19: 55 | E19: =ROUND(B19 * D19,2) -> 2640
A20: Welfare unit | B20: 48 | C20: wks | D20: 50 | E20: =ROUND(B20 * D20,2) -> 2400
A21: Container | B21: 48 | C21: wks | D21: 20 | E21: =ROUND(B21 * D21,2) -> 960
A22: Site toilet | B22: 48 | C22: wks | D22: 30 | E22: =ROUND(B22 * D22,2) -> 1440
A23: Delivery and collection of all site offices, welfare unit, toilets and container | B23: 1 | C23: item | D23: 1580 | E23: =ROUND(B23 * D23,2) -> 1580
A24: Connect site offices and welfare to power and water | B24: 1 | C24: item | D24: 1500 | E24: =ROUND(B24 * D24,2) -> 1500
A25: IT equipment, printing, etc. | B25: =$B$5 -> 48 | C25: wks | D25: 35 | E25: =ROUND(B25 * D25,2) -> 1680
A26: Welfare equipment/tea & coffee, etc. | B26: =$B$5 -> 48 | C26: wks | D26: 15 | E26: =ROUND(B26 * D26,2) -> 720
A27: Security | C27: wks | E27: Excluded
A28: Temp. fencing & barriers | B28: 1 | C28: item | D28: 500 | E28: =ROUND(B28 * D28,2) -> 500
A29: Hardstanding for laydown, turning areas, maintain and reinstate | C29: item | E29: Excluded
A31: Temporary Site Services
A32: Supply & install lighting/power | B32: 1 | C32: item | D32: 2400 | E32: =ROUND(B32 * D32,2) -> 2400
A33: Telephone and internet | B33: =$B$5 -> 48 | C33: wks | D33: 35 | E33: =ROUND(B33 * D33,2) -> 1680
A34: Water connection and supply | B34: 1 | C34: item | D34: 600 | E34: =ROUND(B34 * D34,2) -> 600
A35: Temporary heating and drying | B35: 1 | C35: item | D35: 1500 | E35: =ROUND(B35 * D35,2) -> 1500
A37: Plant, Tools & Equipment
A38: Small Tools | B38: =$B$5 -> 48 | C38: wks | D38: 40 | E38: =ROUND(B38 * D38,2) -> 1920
A39: Forklift hire | B39: =B13 -> 40 | C39: wks | D39: 315 | E39: =ROUND(B39 * D39,2) -> 12600
A41: Scaffolding and Access Equipment
A42: Scaffolding to Compound | B42: 1 | C42: PS | D42: 3500 | E42: =ROUND(B42 * D42,2) -> 3500
A43: Allowance for adaptations | B43: 1 | C43: PS | D43: 0 | E43: =ROUND(B43 * D43,2) -> 0
A44: Alloy towers, hop-ups, trestles & specialist internal access | B44: 1 | C44: item | D44: 1000 | E44: =ROUND(B44 * D44,2) -> 1000
A45: Scaffolding to plots | B45: 8 | C45: plots | D45: 8500 | E45: =ROUND(B45 * D45,2) -> 68000
A47: Clearance & Cleaning
A48: Clear rubbish from site - 12 yard skips | B48: =4*8 -> 32 | C48: nr | D48: 375 | E48: =ROUND(B48 * D48,2) -> 12000
...

Sheet 02 Plot Groundworks
A2: The Former Police Station, Haslingden | D2: PLOT GROUNDWORKS | F2: SECTION 2 | G2: Comments
B4: Description | C4: Quantity | D4: Unit | E4: Rate | F4: Total
B6: Plot Groundworks | F6: =IF(C6="","",(C6*E6))
B8: Block B
F9: =IF(C9="","",(C9*E9))
A10: A | B10: Supply & installation of 150mm block & beam flooring to semi detatched unit (Block B) | C10: 89 | D10: m2 | E10: 65 | F10: =IF(C10="","",(C10*E10)) -> 5785
A12: B | B12: Domestic services to block B | C12: 2 | D12: no | E12: 300 | F12: =IF(C12="","",(C12*E12)) -> 600
A14: C | B14: Facing bricks to DPC (Bradstone) supply and lay | C14: =40*0.45 -> 18 | D14: m2 | E14: 104.25 | F14: =IF(C14="","",(C14*E14)) -> 1876.5
A16: D | B16: Telescopic vents and air bricks | C16: =40/2 -> 20 | D16: no | E16: 9.88 | F16: =IF(C16="","",(C16*E16)) -> 197.6
A18: E | B18: Concrete cavity fill | C18: =47*0.125*0.3 -> 1.7625 | D18: m3 | E18: 256 | F18: =IF(C18="","",(C18*E18)) -> 451.2
A20: F | B20: Supply and lay blockwork to support screed | C20: =54*0.225 -> 12.15 | D20: m2 | E20: 49.2 | F20: =IF(C20="","",(C20*E20)) -> 597.78
B22: Block A
A24: G | B24: Supply & installation of 150mm block & beam flooring to semi detatched unit (Block A) | D24: m2 | F24: Excluded
A26: H | B26: Domestic services to block A | C26: 6 | D26: no | E26: 300 | F26: =IF(C26="","",(C26*E26)) -> 1800
A28: I | B28: Facing bricks to DPC (Bradstone) | D28: m2 | F28: Excluded
A30: J | B30: Telescopic vents and air bricks | D30: no | F30: Excluded
A32: K | B32: Concrete cavity fill | C32: =126*0.125*0.3 -> 4.725 | D32: m3 | E32: 256 | F32: =IF(C32="","",(C32*E32)) -> 1209.6
A34: L | B34: Supply and lay blockwork to support screed | C34: =171*0.225 -> 38.475 | D34: m2 | E34: 49.2 | F34: =IF(C34="","",(C34*E34)) -> 1892.97
D39: To collection | E39: £ | F39: =SUM(F5:F38) -> 14410.65
F44: =IF(C44="","",(C44*E44))
F46: =IF(C46="","",(C46*E46))
F48: =IF(C48="","",(C48*E48))
F50: =IF(C50="","",(C50*E50))
F52: =IF(C52="","",(C52*E52))
F54: =IF(C54="","",(C54*E54))
F56: =IF(C56="","",(C56*E56))
F58: =IF(C58="","",(C58*E58))
F61: =IF(C61="","",(C61*E61))
F62: =IF(C62="","",(C62*E62))
F64: =IF(C64="","",(C64*E64))
F65: =IF(C65="","",(C65*E65))
... F84: =IF(C84="","",(C84*E84))
D87: To collection | E87: £ | F87: =SUM(F44:F86) -> 0
B93: Collection
B95: Page 2/1 | F95: =F39 -> 14410.65
B97: Page 2/2 | F97: =F87 -> 0
F111: =IF(C111="","",(C111*E111))
E112: To Main Summary £ | F112: =SUM(F93:F111) -> 14410.65

Sheet 03 External Groundworks
A2: ='02 Plot Groundworks'!A2 -> The Former Police Station, Haslingden | D2: EXTERNAL GROUNDWORKS | F2: SECTION 3
B4: Description | C4: Quantity | D4: Unit | E4: Rate | F4: Total | G4: Comments
B6: Off site works
B8: Footpath Crossover detail - Manchester road | G8: Actual extent of surfacing required unknown, assumptions made. M2 is provisinal and subject to remeasure upon confirmation. Assumed local authority will not allow patching of tarmac to new kerb line.
A10: A | B10: Existing footway to be excavated and arisings removed from site to accommodate new kerb lines. Assumed depth of 500mm. | C10: =62*0.48 -> 29.76 | D10: m3 | E10: =(68+6.2)*1.2 -> 89.04 | F10: =IF(C10="","",(C10*E10)) -> 2649.8304 | G10: Assumed contaminated cart away, however SI would need to be reviewed in order to sure up costs. | I10: =800/12 -> 66.666667
F11: =IF(C11="","",(C11*E11))
A12: B | B12: Grade, shape and level | C12: 62 | D12: m2 | E12: 1.5 | F12: =IF(C12="","",(C12*E12)) -> 93
F13: =IF(C13="","",(C13*E13))
A14: C | B14: 300mm subbase type 1 stone | C14: =62*0.3 -> 18.6 | D14: m3 | E14: 64 | F14: =IF(C14="","",(C14*E14)) -> 1190.4
F15: =IF(C15="","",(C15*E15))
A16: D | B16: 70mm base course - material 20mm DBM road base | C16: 62 | D16: m2 | E16: 35 | F16: =IF(C16="","",(C16*E16)) -> 2170
F17: =IF(C17="","",(C17*E17))
A18: E | B18: 70mm binder course - material AC20 dense bin binder grade 100/150 | C18: 62 | D18: m2 | E18: 34 | F18: =IF(C18="","",(C18*E18)) -> 2108
F19: =IF(C19="","",(C19*E19))
A20: F | B20: Sweep tack & coat | C20: 62 | D20: m2 | E20: 2 | F20: =IF(C20="","",(C20*E20)) -> 124
F21: =IF(C21="","",(C21*E21))
A22: G | B22: 40mm wearing course - material SMF 10 surf binder grade 40/60 or PMB | C22: 62 | D22: m2 | E22: 31 | F22: =IF(C22="","",(C22*E22)) -> 1922
F23: =IF(C23="","",(C23*E23))
A24: H | B24: New radius kerb line required, 125mm upstand | C24: 12 | D24: m | E24: 32.5 | F24: =IF(C24="","",(C24*E24)) -> 390
F25: =IF(C25="","",(C25*E25))
A26: I | B26: Tactile paving required to crossing point | C26: 4 | D26: m2 | E26: 180 | F26: =IF(C26="","",(C26*E26)) -> 720
F27: =IF(C27="","",(C27*E27))
A28: J | B28: White lining | C28: 1 | D28: item | E28: 1000 | F28: =IF(C28="","",(C28*E28)) -> 1000 | G28: Provisional Sum
F29: =IF(C29="","",(C29*E29))
B30: Footpath Crossover detail - Hazeldene Avenue | F30: =IF(C30="","",(C30*E30)) | G30: Actual extent of surfacing required unknown, assumptions made. M2 is provisinal and subject to remeasure upon confirmation. Assumed local authority will not allow patching of tarmac to new kerb line.
F31: =IF(C31="","",(C31*E31))
A32: K | B32: Removal of exisitng kerbline and footpath to tie in revised makeup, removal off site. | C32: =22*0.48 -> 10.56 | D32: m3 | E32: =(68+6.2)*1.2 -> 89.04 | F32: =IF(C32="","",(C32*E32)) -> 940.2624
F33: =IF(C33="","",(C33*E33))
A34: L | B34: Grade, shape and level | C34: 22 | D34: m2 | E34: 1.5 | F34: =IF(C34="","",(C34*E34)) -> 33
F35: =IF(C35="","",(C35*E35))
A36: M | B36: 300mm subbase type 1 stone | C36: =22*0.3 -> 6.6 | D36: m3 | E36: 64 | F36: =IF(C36="","",(C36*E36)) -> 422.4
F37: =IF(C37="","",(C37*E37))
A38: N | B38: 70mm base course - material 20mm DBM road base | C38: 22 | D38: m2 | E38: 35 | F38: =IF(C38="","",(C38*E38)) -> 770
F39: =IF(C39="","",(C39*E39))
A40: O | B40: 70mm binder course - material AC20 dense bin binder grade 100/150 | C40: 22 | D40: m2 | E40: 34 | F40: =IF(C40="","",(C40*E40)) -> 748
F41: =IF(C41="","",(C41*E41))
A42: P | B42: Sweep tack & coat | C42: 22 | D42: m2 | E42: 2 | F42: =IF(C42="","",(C42*E42)) -> 44
F43: =IF(C43="","",(C43*E43))
A44: Q | B44: 40mm wearing course - material SMF 10 surf binder grade 40/60 or PMB | C44: 22 | D44: m2 | E44: 31 | F44: =IF(C44="","",(C44*E44)) -> 682
F45: =IF(C45="","",(C45*E45))
...

Sheet 04 External Facade
A2: ='02 Plot Groundworks'!A2 -> The Former Police Station, Haslingden | D2: EXTERNAL FAÇADE | F2: SECTION 4
B4: Description | C4: Quantity | D4: Unit | E4: Rate | F4: Total | G4: Comments
B6: External Façade
B8: BLOCK A
A10: A | B10: Installation of radon DPC, lapped and taped to DPM | C10: 77 | D10: m | E10: 6.5 | F10: =IF(C10="","",(C10*E10)) -> 500.5
F11: =IF(C11="","",(C11*E11))
A12: B | B12: Installation of 100m bradstone or similar bed coursed artificial stone above DPC | C12: =326*1.1 -> 358.6 | D12: m2 | E12: 55 | F12: =IF(C12="","",(C12*E12)) -> 19723
A14: C | B14: Installation of 125mm cavity partially filled with 75mm Kingspan TW Thermawall cavity board | C14: =C16 -> 448 | D14: m2 | E14: 3.5 | F14: =IF(C14="","",(C14*E14)) -> 1568
A16: D | B16: Installation of 100mm concrete blockwork to inner leaf above DPC | C16: 448 | D16: m2 | E16: 22 | F16: =IF(C16="","",(C16*E16)) -> 9856
A18: E | B18: Installation of 100mm blockwork to internal walls | C18: =((15*2.5)*6)*1.1 -> 247.5 | D18: m2 | E18: 22 | F18: =IF(C18="","",(C18*E18)) -> 5445
A20: F | B20: Installation of 100mm concrete blocks to party wall including gable, lightweight aggregate blocks | C20: 838.1 | D20: m2 | E20: 22 | F20: =IF(C20="","",(C20*E20)) -> 18438.2
A22: G | B22: Installation of 100mm Isover RD Party Wall Insulation | C22: 419.01 | D22: m2 | E22: 3.5 | F22: =IF(C22="","",(C22*E22)) -> 1466.535
A24: H | B24: Installation of 100mm concrete blockwork to outer leaf to rendered sections including any bed joint reinforcement required | C24: =123*1.1 -> 135.3 | D24: m2 | E24: 22 | F24: =IF(C24="","",(C24*E24)) -> 2976.6
F25: =IF(C25="","",(C25*E25))
A26: I | B26: Installation of steel lintels | C26: =67+4 -> 71 | D26: m | E26: 19.5 | F26: =IF(C26="","",(C26*E26)) -> 1384.5
F27: =IF(C27="","",(C27*E27))
A28: J | B28: Installation of Ashlar stone heads and cills | C28: =46+59 -> 105 | D28: m | E28: 37.5 | F28: =IF(C28="","",(C28*E28)) -> 3937.5
F29: =IF(C29="","",(C29*E29))
A30: K | B30: DPC / Cavity trays required | C30: =C26 -> 71 | D30: m | E30: 6.5 | F30: =IF(C30="","",(C30*E30)) -> 461.5
F31: =IF(C31="","",(C31*E31))
A32: L | B32: Fixing of cavity formers | C32: 48 | D32: no | E32: 5 | F32: =IF(C32="","",(C32*E32)) -> 240
A34: M | B34: Jet wash / make good | C34: 6 | D34: no | E34: 225 | F34: =IF(C34="","",(C34*E34)) -> 1350
A36: N | B36: Service boxes | C36: 6 | D36: no | E36: 30 | F36: =IF(C36="","",(C36*E36)) -> 180
F37: =IF(C37="","",(C37*E37))
B38: BLOCK B | F38: =IF(C38="","",(C38*E38))
F39: =IF(C39="","",(C39*E39))
A40: O | B40: Installation of radon DPC, lapped and taped to DPM | C40: 40 | D40: m | E40: 6.5 | F40: =IF(C40="","",(C40*E40)) -> 260
F41: =IF(C41="","",(C41*E41))
A42: P | B42: Installation of 100m bradstone or similar bed coursed artificial stone above DPC | C42: =192*1.1 -> 211.2 | D42: m2 | E42: 55 | F42: =IF(C42="","",(C42*E42)) -> 11616
F43: =IF(C43="","",(C43*E43))
A44: Q | B44: Installation of 125mm cavity partially filled with 75mm Kingspan TW Thermawall cavity board | C44: =C46 -> 256.2 | D44: m2 | E44: 3.5 | F44: =IF(C44="","",(C44*E44)) -> 896.7
F45: =IF(C45="","",(C45*E45))
A46: R | B46: Installation of 100mm concrete blockwork to inner leaf above DPC | C46: =C52+C42 -> 256.2 | D46: m2 | E46: 22 | F46: =IF(C46="","",(C46*E46)) -> 5636.4
A48: S | B48: Installation of 100mm concrete blocks to party wall including gable, lightweight aggregate blocks | C48: 138 | D48: m2 | E48: 22 | F48: =IF(C48="","",(C48*E48)) -> 3036
F49: =IF(C49="","",(C49*E49))
A50: T | B50: Installation of 100mm Isover RD Party Wall Insulation | C50: 69 | D50: m2 | E50: 3.5 | F50: =IF(C50="","",(C50*E50)) -> 241.5
A52: U | B52: Installation of 100mm concrete blockwork to outer leaf to rendered sections including any bed joint reinforcement required | C52: 45 | D52: m2 | E52: 22 | F52: =IF(C52="","",(C52*E52)) -> 990
F53: =IF(C53="","",(C53*E53))
A54: V | B54: Installation of steel lintels | C54: =3+24+2 -> 29 | D54: m | E54: 19.5 | F54: =IF(C54="","",(C54*E54)) -> 565.5
F55: =IF(C55="","",(C55*E55))
...

Sheet 05 Drylining, Screed & Render
A2: ='02 Plot Groundworks'!A2 -> The Former Police Station, Haslingden | D2: DRYLINING, SCREED | F2: SECTION 5
D3: RENDER
B4: Description | C4: Quantity | D4: Unit | E4: Rate | F4: Total | G4: Comments
B5: Block A
A7: A | B7: 75mm sand and cement screed laid on 150mm PIR Kingspan Thermafloor TF70 insulation, Gas Radon DPM. | C7: 256 | D7: m2 | E7: 55 | F7: =IF(C7="","",(C7*E7)) -> 14080
F8: =IF(C8="","",(C8*E8))
B9: Ceilings | F9: =IF(C9="","",(C9*E9))
F10: =IF(C10="","",(C10*E10))
A11: B | B11: 1no layer of 15mm wallboard | D11: m2 | F11: =IF(C11="","",(C11*E11))
F12: =IF(C12="","",(C12*E12))
A13: C | B13: 1no layer of 15mm fireline wallboard | C13: =((43*6)*2)+(29*4.49) -> 646.21 | D13: m2 | E13: 12.5 | F13: =IF(C13="","",(C13*E13)) -> 8077.625
F14: =IF(C14="","",(C14*E14))
A15: D | B15: Skeilings - 120mm Kooltherm K107, 82.5mm Kooltherm K118 Insulated Board | C15: =3.9*29 -> 113.1 | D15: m2 | E15: 70 | F15: =IF(C15="","",(C15*E15)) -> 7917
F16: =IF(C16="","",(C16*E16))
A17: E | B17: EO moisture board | C17: =(2.13+4.37+5.34)*6 -> 71.04 | D17: m2 | E17: 7.25 | F17: =IF(C17="","",(C17*E17)) -> 515.04
F18: =IF(C18="","",(C18*E18))
A19: F | B19: Eo tape & joint | C19: =C15+C13 -> 759.31 | D19: m2 | E19: 6 | F19: =IF(C19="","",(C19*E19)) -> 4555.86
A21: G | B21: EO Skim Finish | C21: =C15+C13 -> 759.31 | D21: m2 | E21: 7 | F21: =IF(C21="","",(C21*E21)) -> 5315.17
F22: =IF(C22="","",(C22*E22))
B23: Walls | F23: =IF(C23="","",(C23*E23))
F24: =IF(C24="","",(C24*E24))
A25: H | B25: Dot & dab external walls | C25: =((58*2.5)*6) -> 870 | D25: m2 | E25: 11.6 | F25: =IF(C25="","",(C25*E25)) -> 10092
F26: =IF(C26="","",(C26*E26))
A27: I | B27: Dot & dab internal blockwork walls | C27: =(29*2.5)*6 -> 435 | D27: m2 | E27: 11.6 | F27: =IF(C27="","",(C27*E27)) -> 5046
F28: =IF(C28="","",(C28*E28))
A29: J | B29: Metal partitions - 12.5mm Board, 50mm Gyplyner, 12.5mm board | D29: m2 | F29: =IF(C29="","",(C29*E29))
F30: =IF(C30="","",(C30*E30))
A31: K | B31: Metal partitions with insulation - 12.5mm Board, 50mm Gyplyner, 50mm Isover, 12.5mm board | D31: m2 | F31: =IF(C31="","",(C31*E31))
F32: =IF(C32="","",(C32*E32))
A33: L | B33: Timber Partitions with Insulation - 12.5mm Board, 89 Timber Stud(by Others), 50mm Isover, 12.5mm board | C33: =((17*2.5)*6)+((13*2.5)*6) -> 450 | D33: m2 | E33: 11.52 | F33: =IF(C33="","",(C33*E33)) -> 5184
F34: =IF(C34="","",(C34*E34))
A35: M | B35: Timber Partitions (Dwarf Walls) - 12.5mm Board, 89 Timber Stud(by Others), 50mm Isover, 12.5mm board | C35: =12.76*6 -> 76.56 | D35: m2 | E35: 11.52 | F35: =IF(C35="","",(C35*E35)) -> 881.9712
F36: =IF(C36="","",(C36*E36))
A37: N | B37: Eo Ply patressing | D37: m2 | F37: =IF(C37="","",(C37*E37))
F38: =IF(C38="","",(C38*E38))
A39: O | B39: Eo moisture board | C39: =(((9*2.5)+0.66)*6)+((6.25*2.5)*6)+((9.25*2.5)*6) -> 371.46 | D39: m2 | E39: 7.25 | F39: =IF(C39="","",(C39*E39)) -> 2693.085
F40: =IF(C40="","",(C40*E40))
A41: P | B41: Eo tape & joint | C41: =C35+C33+C27+C25 -> 1831.56 | D41: m2 | E41: 6 | F41: =IF(C41="","",(C41*E41)) -> 10989.36
F42: =IF(C42="","",(C42*E42))
D44: To collection | E44: £ | F44: =SUM(F5:F43) -> 75347.111
...

Sheet 06 M&E
A2: =Summary!A2 -> The Former Police Station, Haslingden | D2: MECHANICAL & ELECTRICAL | F2: SECTION 6
B4: Description | C4: Quantity | D4: Unit | E4: Rate | F4: Total | G4: Comments
B6: Block A
A8: A | B8: Mechanical Provisional sum allowed for each unit. Mechanical drawings required along with a full client spec to be able to price works fully. Thermostatic heating system, Baxi Ecoblue 32 system boiler with cylinder. | C8: 6 | D8: plots | E8: 16800 | F8: =IF(C8="","",(C8*E8)) -> 100800 | G8: Including basic sanitaryware spec. Awaiting further confirmation.
B10: Block B
A12: B | B12: Mechanical Provisional sum allowed for each unit. Mechanical drawings required along with a full client spec to be able to price works fully. Thermostatic heating system, Baxi Ecoblue 32 system boiler with cylinder. | C12: 2 | D12: plots | E12: 16800 | F12: =IF(C12="","",(C12*E12)) -> 33600 | G12: Including basic sanitaryware spec. Awaiting further confirmation.
B14: Block A
A16: C | B16: Based on BG electrical Nexus accessories, need confirmation on exact spec. Allowed for white accessories only, pendant light fittings throughout. No allowance for any vehicle car charging points. | C16: 6 | D16: plots | E16: 4250 | F16: =IF(C16="","",(C16*E16)) -> 25500
B18: Block B
A20: D | B20: Based on BG electrical Nexus accessories, need confirmation on exact spec. Allowed for white accessories only, pendant light fittings throughout. No allowance for any vehicle car charging points. | C20: 2 | D20: plots | E20: 4250 | F20: =IF(C20="","",(C20*E20)) -> 8500
G26: =IF(D26="","",(D26*F26))
G27: =IF(D27="","",(D27*F27))
G30: =IF(D30="","",(D30*F30))
G31: =IF(D31="","",(D31*F31))
D38: To collection | E38: £ | F38: =SUM(F6:F36) -> 168400
D74: To collection | E74: £ | F74: =SUM(F40:F72) -> 0
F76: =IF(C76="","",(C76*E76))
C99: To Main Summary £ | F99: =SUM(F76:F97) -> 0

Sheet 07 Carpentry
A2: ='02 Plot Groundworks'!A2 -> The Former Police Station, Haslingden | D2: CARPENTRY | F2: SECTION 7
B4: Description | C4: Quantity | D4: Unit | E4: Rate | F4: Total | G4: Comments
B6: Block A
A8: A | B8: Externals
A10: B | B10: Easi joist floor system at 400mm centers including 22mm T&G chipboard decking incl trimming out, temp bracing & perimeter noggins | C10: =45*6 -> 270 | D10: m2 | E10: 19 | F10: =IF(C10="","",(C10*E10)) -> 5130
F11: =IF(C11="","",(C11*E11))
A12: C | B12: Cut & fix wall / pole plate (including halving joints where required). | C12: =29*6 -> 174 | D12: m | E12: 3 | F12: =IF(C12="","",(C12*E12)) -> 522
F13: =IF(C13="","",(C13*E13))
A14: D | B14: Attic trusses inc all fixings | C14: 72 | D14: no | E14: 45 | F14: =IF(C14="","",(C14*E14)) -> 3240
F15: =IF(C15="","",(C15*E15))
A16: E | B16: Fix 100 x 25mm longitudinal bracing to trusses (no detail, assummed) | C16: 6 | D16: plot | E16: 75 | F16: =IF(C16="","",(C16*E16)) -> 450
F17: =IF(C17="","",(C17*E17))
A18: F | B18: Install lateral restraint straps (on support noggins). | C18: =C12/2+1 -> 88 | D18: each | E18: 2.5 | F18: =IF(C18="","",(C18*E18)) -> 220
F19: =IF(C19="","",(C19*E19))
A20: G | B20: Cut & fix UPVC fascia board. | C20: =28.12*2 -> 56.24 | D20: m | E20: 4 | F20: =IF(C20="","",(C20*E20)) -> 224.96
F21: =IF(C21="","",(C21*E21))
A22: H | B22: Cut & fix bargeboard | C22: =13*2 -> 26 | D22: m | E22: 4 | F22: =IF(C22="","",(C22*E22)) -> 104
F23: =IF(C23="","",(C23*E23))
A24: I | B24: Cut & fix UPVC soffit. | C24: =C20+C22 -> 82.24 | D24: m | E24: 4 | F24: =IF(C24="","",(C24*E24)) -> 328.96
F25: =IF(C25="","",(C25*E25))
A26: J | B26: Fix Velux Window | C26: 18 | D26: no | E26: 50 | F26: =IF(C26="","",(C26*E26)) -> 900
F27: =IF(C27="","",(C27*E27))
B28: 1st Fix | F28: =IF(C28="","",(C28*E28))
F29: =IF(C29="","",(C29*E29))
A30: K | B30: Fix pre-hung PAS 24 entrance door set with pre-fitted muliti point lock (20mm total packing max) (sub-frame excluded). | C30: 6 | D30: plot | E30: 100 | F30: =IF(C30="","",(C30*E30)) -> 600
F31: =IF(C31="","",(C31*E31))
A32: L | B32: Cut protection panels from 9mm plywood for bath & shower tray (hand to plumber for installation). | C32: 6 | D32: set | E32: 50 | F32: =IF(C32="","",(C32*E32)) -> 300
F33: =IF(C33="","",(C33*E33))
A34: M | B34: Cut & fix window board (mdf, pre formed) (brackets supplied by Client) (window to be fitted with receiver groove by others). | C34: 36 | D34: m | E34: 5 | F34: =IF(C34="","",(C34*E34)) -> 180
F35: =IF(C35="","",(C35*E35))
A36: N | B36: Application of free-issue expanding foam to void below window cill. | C36: =C34 -> 36 | D36: m | E36: 1 | F36: =IF(C36="","",(C36*E36)) -> 36
F37: =IF(C37="","",(C37*E37))
A38: O | B38: Removal of sacraficial joists, hangers, flooring & access hatch to stairwell prior to stair installation. | C38: 12 | D38: floor | E38: 50 | F38: =IF(C38="","",(C38*E38)) -> 600
F39: =IF(C39="","",(C39*E39))
A40: P | B40: Install pre-assembled sw stair case (kite top & bottom) (full assembly & installation inclusive of string mounted newel posts, framing to support base of stair case & "T" bar support to rear of 1st riser). | C40: 12 | D40: each | E40: 450 | F40: =IF(C40="","",(C40*E40)) -> 5400
F41: =IF(C41="","",(C41*E41))
A42: Q | B42: Install temporary handrail to stair perimeter. | C42: 12 | D42: floor | E42: 75 | F42: =IF(C42="","",(C42*E42)) -> 900
C45: To Main Summary £ | F45: =SUM(F6:F44) -> 19135.92
A48: R | B48: Application of protection to staircase (materials provided by Client). | C48: 12 | D48: each | E48: 20 | F48: =IF(C48="","",(C48*E48)) -> 240
F49: =IF(C49="","",(C49*E49))
...

Sheet 08 Roof Coverings
A2: =Summary!A2 -> The Former Police Station, Haslingden | D2: ROOF COVERINGS | F2: SECTION 8
B4: Description | C4: Quantity | D4: Unit | E4: Rate | F4: Total | G4: Comments
B6: Block A
A8: A | B8: Main roofs and canopies - Sobrano brazilian grey / green natural slate. Battened out to the appropriate gauge and fixed to a breather membrane. To include all ridge and verge operations as well as leadwork where required. Porches to be smaller format tiles. | C8: =((6.334*2)*28.175)+16.52 -> 373.4409 | D8: m2 | E8: 135 | F8: =IF(C8="","",(C8*E8)) -> 50414.521
B10: Block B
A12: B | B12: Main roofs and canopies - Sobrano brazilian grey / green natural slate. Battened out to the appropriate gauge and fixed to a breather membrane. To include all ridge and verge operations as well as leadwork where required. Porches to be smaller format tiles. | C12: =((5.538*2)*10.85)+5.51 -> 125.6846 | D12: m2 | E12: 135 | F12: =IF(C12="","",(C12*E12)) -> 16967.421
G26: =IF(D26="","",(D26*F26))
G27: =IF(D27="","",(D27*F27))
G30: =IF(D30="","",(D30*F30))
G31: =IF(D31="","",(D31*F31))
D38: To collection | E38: £ | F38: =SUM(F6:F36) -> 67381.943
D74: To collection | E74: £ | F74: =SUM(F40:F72) -> 0
F76: =IF(C76="","",(C76*E76))
C99: To Main Summary £ | F99: =SUM(F76:F97) -> 0

Sheet 09 Decorating & Other Finishing
A2: ='02 Plot Groundworks'!A2 -> The Former Police Station, Haslingden | D2: DECORATION | F2: SECTION 9
D3: & OTHER FINISHING TRADES
B4: Description | C4: Quantity | D4: Unit | E4: Rate | F4: Total | G4: Comments
B6: Decoration
B8: Block A
A10: A | B10: Decoration, emulsion to walls and ceilings with glosswork for all internal woodwork. | C10: 7686 | D10: £/SQFT | E10: 4 | F10: =IF(C10="","",(C10*E10)) -> 30744 | G10: Assumed no colours or wallpapering, no coving or any other ornate details. Assumed timeless white to both walls and ceilings.
B12: Block B
A14: B | B14: Decoration, emulsion to walls and ceilings with glosswork for all internal woodwork. | C14: 2456 | D14: £/SQFT | E14: 4 | F14: =IF(C14="","",(C14*E14)) -> 9824 | G14: Assumed no colours or wallpapering, no coving or any other ornate details. Assumed dulux timeless white to both walls and ceilings.
B16: Mastic
B18: Block A
A20: C | B20: Mastic works to internal floor junctions for tiled / laminate flooring, internal window frames, junction between wall tiling and wall, kitchen worktop corner junction between wall tiling. Externals - around window frames, meter box, movement joints, porches (where required) | C20: 7686 | D20: £/SQFT | E20: 0.5 | F20: =IF(C20="","",(C20*E20)) -> 3843
B22: Block B
A24: D | B24: Mastic works to internal floor junctions for tiled / laminate flooring, internal window frames, junction between wall tiling and wall, kitchen worktop corner junction between wall tiling. Externals - around window frames, meter box, movement joints, porches (where required) | C24: 2456 | D24: £/SQFT | E24: 0.5 | F24: =IF(C24="","",(C24*E24)) -> 1228
F25: =IF(C25="","",(C25*E25))
B26: Kitchens
B28: Block A | F28: =IF(C28="","",(C28*E28))
F29: =IF(C29="","",(C29*E29))
A30: E | B30: Kitchen supply and installation including appliacnes and standard 45mm MDF worktop. Spec required in order to sure up pricing for this element of works. | C30: 6 | D30: plot | E30: 12500 | F30: =IF(C30="","",(C30*E30)) -> 75000 | G30: No allowance for granite unless otherwise specified. Appliances allowed from the Bosch group. Oven, hob, extractor, FF, Dishwasher & washing machine.
F31: =IF(C31="","",(C31*E31))
B32: Block B | F32: =IF(C32="","",(C32*E32))
F33: =IF(C33="","",(C33*E33))
A34: F | B34: Kitchen supply and installation including appliacnes and standard 45mm MDF worktop. Spec required in order to sure up pricing for this element of works. | C34: 2 | D34: plot | E34: 12500 | F34: =IF(C34="","",(C34*E34)) -> 25000 | G34: No allowance for granite unless otherwise specified. Appliances allowed from the Bosch group. Oven, hob, extractor, FF, Dishwasher & washing machine
F35: =IF(C35="","",(C35*E35))
B36: Wall tiling | F36: =IF(C36="","",(C36*E36)) | G36: Tiling spec to be from the basic range from Porcelonsa.
F37: =IF(C37="","",(C37*E37))
B38: Block A | F38: =IF(C38="","",(C38*E38))
F39: =IF(C39="","",(C39*E39))
A40: G | B40: WC - half height around sanitaryware walls, 2 sides | C40: =(3.13*1.25)*6 -> 23.475 | D40: m2 | E40: 75 | F40: =IF(C40="","",(C40*E40)) -> 1760.625
A41: H | B41: Bathroom - half height and shelf tiled, full height around bath | C41: =((2*1.2)+(2*0.33)+(2.58*2))*6 -> 49.32 | D41: m2 | E41: 75 | F41: =IF(C41="","",(C41*E41)) -> 3699
A42: I | B42: Ensuite - half height tiling to wash hand basin wall | C42: =(2.38*1.2)*6 -> 17.136 | D42: m2 | E42: 75 | F42: =IF(C42="","",(C42*E42)) -> 1285.2
A43: J | B43: Ensuite - tiled dwarf wall (not skeiling) | C43: =(2.24*1.5)*6 -> 20.16 | D43: m2 | E43: 75 | F43: =IF(C43="","",(C43*E43)) -> 1512
A44: K | B44: Ensuite - full height tiling around shower | C44: =(1.63*2.5)*6 -> 24.45 | D44: m2 | E44: 75 | F44: =IF(C44="","",(C44*E44)) -> 1833.75
F45: =IF(C45="","",(C45*E45))
B46: Block B | F46: =IF(C46="","",(C46*E46))
F47: =IF(C47="","",(C47*E47))
A48: L | B48: WC - half height around sanitaryware walls, 2 sides | C48: =(3.25*1.25)*2 -> 8.125 | D48: m2 | E48: 75 | F48: =IF(C48="","",(C48*E48)) -> 609.375
A49: M | B49: Bathroom - half height and shelf tiled, full height around bath | C49: =((2*1.2)+(2*0.33)+(2.4*2))*2 -> 15.72 | D49: m2 | E49: 75 | F49: =IF(C49="","",(C49*E49)) -> 1179
A50: N | B50: Ensuite - half height tiling to wash hand basin wall | C50: =(1.93*1.2)*2 -> 4.632 | D50: m2 | E50: 75 | F50: =IF(C50="","",(C50*E50)) -> 347.4
A51: O | B51: Ensuite - tiled dwarf wall (not skeiling) | C51: =(2.84*1.2)*2 -> 6.816 | D51: m2 | E51: 75 | F51: =IF(C51="","",(C51*E51)) -> 511.2
A52: P | B52: Ensuite - full height tiling around shower | C52: =(1.63*2.5)*2 -> 8.15 | D52: m2 | E52: 75 | F52: =IF(C52="","",(C52*E52)) -> 611.25
...

Sheet 10 Materials
A2: ='02 Plot Groundworks'!A2 -> The Former Police Station, Haslingden | D2: MATERIALS | F2: SECTION 10
B4: Description | C4: Quantity | D4: Unit | E4: Rate | F4: Total | G4: Comments
B6: BLOCK A
A8: A | B8: Radon DPC | C8: 77 | D8: m | E8: 9 | F8: =IF(C8="","",(C8*E8)) -> 693
F9: =IF(C9="","",(C9*E9))
A10: B | B10: 100m bradstone or similar bed coursed artificial stone above DPC | C10: =326*1.1 -> 358.6 | D10: m2 | E10: 41 | F10: =IF(C10="","",(C10*E10)) -> 14702.6
F11: =IF(C11="","",(C11*E11))
A12: C | B12: 75mm Kingspan TW Thermawall cavity board | C12: 448 | D12: m2 | E12: 38 | F12: =IF(C12="","",(C12*E12)) -> 17024
A14: D | B14: 100mm concrete blockwork to inner leaf above DPC | C14: 448 | D14: m2 | E14: 19 | F14: =IF(C14="","",(C14*E14)) -> 8512
F15: =IF(C15="","",(C15*E15))
A16: E | B16: 100mm blockwork to internal walls | C16: =((15*2.5)*6)*1.1 -> 247.5 | D16: m2 | E16: 19 | F16: =IF(C16="","",(C16*E16)) -> 4702.5
A18: F | B18: 100mm concrete blocks to party wall including gable, lightweight aggregate blocks | C18: 838 | D18: m2 | E18: 20 | F18: =IF(C18="","",(C18*E18)) -> 16760
A20: G | B20: 100mm Isover RD Party Wall Insulation | C20: 419 | D20: m2 | E20: 9.5 | F20: =IF(C20="","",(C20*E20)) -> 3980.5
A22: H | B22: 100mm concrete blockwork to outer leaf to rendered sections including any bed joint reinforcement required | C22: 135 | D22: m2 | E22: 20 | F22: =IF(C22="","",(C22*E22)) -> 2700
A24: I | B24: Steel lintels | C24: 71 | D24: m | E24: 47.5 | F24: =IF(C24="","",(C24*E24)) -> 3372.5
A26: J | B26: Ashlar stone heads and cills | C26: 105 | D26: m | E26: 118 | F26: =IF(C26="","",(C26*E26)) -> 12390
A28: K | B28: DPC / Cavity Trays | C28: 71 | D28: m | E28: 0.65 | F28: =IF(C28="","",(C28*E28)) -> 46.15
A30: L | B30: Mortar | C30: =C22+C18+C16+C14+C10 -> 2027.1 | D30: m2 | E30: 6.1 | F30: =IF(C30="","",(C30*E30)) -> 12365.31 | H30: 90 | I30: m3
H31: Brick | I31: 0.108 | J31: =SUM(C10) -> 358.6 | K31: =J31*I31 -> 38.7288 | L31: =K31*H30 -> 3485.592
A32: M | B32: Cavity Formers | C32: 6 | D32: plots | E32: 400 | F32: =IF(C32="","",(C32*E32)) -> 2400 | H32: Block | I32: 0.059 | J32: =SUM(C22+C18+C16+C14) -> 1668.5 | K32: =J32*I32 -> 98.4415 | L32: =K32*H30 -> 8859.735
F33: =IF(C33="","",(C33*E33))
A34: N | B34: Misc brickwork sundries | C34: 6 | D34: plots | E34: 150 | F34: =IF(C34="","",(C34*E34)) -> 900 | L34: =SUM(L31:L32) -> 12345.327
A36: O | B36: Easi joists | C36: 6 | D36: plots | E36: 1700 | F36: =IF(C36="","",(C36*E36)) -> 10200
F37: =IF(C37="","",(C37*E37))
A38: P | B38: Attic Trusses | C38: 6 | D38: plots | E38: 6500 | F38: =IF(C38="","",(C38*E38)) -> 39000
F39: =IF(C39="","",(C39*E39))
A40: Q | B40: Fascia, Soffit & bargeboard | C40: 6 | D40: plots | E40: 550 | F40: =IF(C40="","",(C40*E40)) -> 3300
F41: =IF(C41="","",(C41*E41))
A42: R | B42: Velux windows - large | C42: 12 | D42: no | E42: 850 | F42: =IF(C42="","",(C42*E42)) -> 10200
F43: =IF(C43="","",(C43*E43))
A44: S | B44: Velux windows - small | C44: 6 | D44: no | E44: 550 | F44: =IF(C44="","",(C44*E44)) -> 3300
F45: =IF(C45="","",(C45*E45))
A46: T | B46: Staircases | C46: 6 | D46: plots | E46: 1375 | F46: =IF(C46="","",(C46*E46)) -> 8250 | G46: Including pre assembled ballustrade and handrail
F47: =IF(C47="","",(C47*E47))
A48: U | B48: Lean too Porches | C48: 6 | D48: plots | E48: 575 | F48: =IF(C48="","",(C48*E48)) -> 3450
F49: =IF(C49="","",(C49*E49))
A50: V | B50: 1st fix timbers | C50: 6 | D50: plots | E50: 350 | F50: =IF(C50="","",(C50*E50)) -> 2100
F51: =IF(C51="","",(C51*E51))
A52: W | B52: Internal doors - FD20 | C52: =6*6 -> 36 | D52: items | E52: 105 | F52: =IF(C52="","",(C52*E52)) -> 3780 | G52: Vertical 5 paneled primed, to be painted white on site.
F53: =IF(C53="","",(C53*E53))
...

Sheet 11 Landscaping
A2: ='02 Plot Groundworks'!A2 -> The Former Police Station, Haslingden | D2: LANDSCAPING | F2: SECTION 11
B4: Description | C4: Quantity | D4: Unit | E4: Rate | F4: Total | G4: Comments
B6: Landscaping | G6: No containised stock allowed. No ongoing maintence of turf or plants allowed, this can be allowed as an extra over. Rates include layer of organic mulch to trees, shrubs, plants and specimens.
A8: A | B8: Heavy standard tress av height 350cm - 425cm | C8: 2 | D8: no | E8: 750 | F8: =IF(C8="","",(C8*E8)) -> 1500
F9: =IF(C9="","",(C9*E9))
A10: B | B10: Shrubs - variety mix av height 30 - 60cm | C10: 128 | D10: no | E10: 13 | F10: =IF(C10="","",(C10*E10)) -> 1664
F11: =IF(C11="","",(C11*E11))
A12: C | B12: Specimens - av height 60 - 100cm | C12: 8 | D12: no | E12: 26 | F12: =IF(C12="","",(C12*E12)) -> 208
A14: D | B14: Hedges - double staggered row, av height 60 - 80cm | C14: 168 | D14: no | E14: 14.5 | F14: =IF(C14="","",(C14*E14)) -> 2436
F15: =IF(C15="","",(C15*E15))
A16: E | B16: Turfing allowed to landscaped areas | C16: 55 | D16: m2 | E16: 8 | F16: =IF(C16="","",(C16*E16)) -> 440
A18: F | B18: Turfing to front and rear gardens | C18: 262 | D18: m2 | E18: 8 | F18: =IF(C18="","",(C18*E18)) -> 2096
F20: =IF(C20="","",(C20*E20))
F22: =IF(C22="","",(C22*E22))
F24: =IF(C24="","",(C24*E24))
F26: =IF(C26="","",(C26*E26))
F28: =IF(C28="","",(C28*E28))
F30: =IF(C30="","",(C30*E30))
F32: =IF(C32="","",(C32*E32))
F33: =IF(C33="","",(C33*E33))
F34: =IF(C34="","",(C34*E34))
F35: =IF(C35="","",(C35*E35))
F36: =IF(C36="","",(C36*E36))
F37: =IF(C37="","",(C37*E37))
... F61: =IF(C61="","",(C61*E61))
D64: To collection | E64: £ | F64: =SUM(F5:F61) -> 8344
F69: =IF(C69="","",(C69*E69))
F70: =IF(C70="","",(C70*E70))
F71: =IF(C71="","",(C71*E71))
F72: =IF(C72="","",(C72*E72))
F73: =IF(C73="","",(C73*E73))
F81: =IF(C81="","",(C81*E81))
F83: =IF(C83="","",(C83*E83))
F85: =IF(C85="","",(C85*E85))
F87: =IF(C87="","",(C87*E87))
F89: =IF(C89="","",(C89*E89))
F91: =IF(C91="","",(C91*E91))
F93: =IF(C93="","",(C93*E93))
... F122: =IF(C122="","",(C122*E122))
D125: To collection | E125: £ | F125: =SUM(F66:F115) -> 0

Sheet 12 Walls & Fences
A2: ='02 Plot Groundworks'!A2 -> The Former Police Station, Haslingden | D2: WALLS & FENCES | F2: SECTION 12
B4: Description | C4: Quantity | D4: Unit | E4: Rate | F4: Total | G4: Comments
B6: Boundary walls
A8: A | B8: 1.2m high natural stone wall with 0.6m high timber fence attached | C8: 33 | D8: m | E8: 314 | F8: =IF(C8="","",(C8*E8)) -> 10362
F9: =IF(C9="","",(C9*E9))
A10: B | B10: 1.2m high natural stone wall (215mm wide) | C10: 58 | D10: m | E10: 264 | F10: =IF(C10="","",(C10*E10)) -> 15312 | H10: £ | I10: 60 | J10: m2 | K10: lay | L10: =I10*2 -> 120
F11: =IF(C11="","",(C11*E11)) | H11: £ | I11: 41 | J11: m2 | K11: Bricks | L11: =I11*2 -> 82
B12: Fencing | F12: =IF(C12="","",(C12*E12)) | H12: £ | I12: 6 | J12: m2 | K12: mortar | L12: =I12*2 -> 12
F13: =IF(C13="","",(C13*E13)) | H13: £ | I13: 3 | J13: m2 | K13: sundries | L13: =I13*2 -> 6
A14: C | B14: 1.8m high timber closeboard fence | C14: 168 | D14: m | E14: 65 | F14: =IF(C14="","",(C14*E14)) -> 10920
F15: =IF(C15="","",(C15*E15)) | L15: =SUM(L10:L14) -> 220
B16: Gates | F16: =IF(C16="","",(C16*E16)) | L16: 1.2
F17: =IF(C17="","",(C17*E17)) | L17: =L15*L16 -> 264
A18: D | B18: 1.2m high timber pedestrian gate | C18: 8 | D18: no | E18: 200 | F18: =IF(C18="","",(C18*E18)) -> 1600 | K18: timber fence | L18: 50
F19: =IF(C19="","",(C19*E19)) | L19: =L17+L18 -> 314
A20: E | B20: 1.8m high timber closeboard gate | C20: 8 | D20: no | E20: 250 | F20: =IF(C20="","",(C20*E20)) -> 2000
A22: F | B22: 2.65m wide timber vehicle gates | C22: 2 | D22: no | E22: 850 | F22: =IF(C22="","",(C22*E22)) -> 1700 | G22: Assumed timber
F24: =IF(C24="","",(C24*E24))
F26: =IF(C26="","",(C26*E26))
F28: =IF(C28="","",(C28*E28))
F30: =IF(C30="","",(C30*E30))
F32: =IF(C32="","",(C32*E32))
F33: =IF(C33="","",(C33*E33))
F34: =IF(C34="","",(C34*E34))
F35: =IF(C35="","",(C35*E35))
F36: =IF(C36="","",(C36*E36))
F37: =IF(C37="","",(C37*E37))
F38: =IF(C38="","",(C38*E38))
F39: =IF(C39="","",(C39*E39))
... F61: =IF(C61="","",(C61*E61))
D64: To collection | E64: £ | F64: =SUM(F5:F61) -> 41894
F69: =IF(C69="","",(C69*E69))
F70: =IF(C70="","",(C70*E70))
F71: =IF(C71="","",(C71*E71))
F72: =IF(C72="","",(C72*E72))
F73: =IF(C73="","",(C73*E73))
F81: =IF(C81="","",(C81*E81))
F83: =IF(C83="","",(C83*E83))
F85: =IF(C85="","",(C85*E85))
F87: =IF(C87="","",(C87*E87))
...
